Workbook
Name NativeTimeline_Data_Corrigida: #N/A
Name SegmentaçãodeDados_Família: #N/A
Name SegmentaçãodeDados_Família1: #N/A
Name SegmentaçãodeDados_Mês: #N/A
Name SegmentaçãodeDados_Mês1: #N/A
Name SegmentaçãodeDados_Turno: #N/A
Name SegmentaçãodeDados_Turno1: #N/A

Sheet Tabela Sobrepeso Dia
A4: SOBREPESO EM GRAMAS
A5: Média de Desvio | B5: Rótulos de Coluna
A6: FAMÍLIA | B6: 46296 | C6: 46297 | D6: 46300 | E6: 46301 | F6: 46302 | G6: 46303 | H6: 46304 | I6: 46308 | J6: Total Geral
A7: ASA | B7: 31 | C7: 63.18 | D7: 65.86 | E7: 102.66667 | F7: 75.64 | G7: 27.25 | H7: 29 | J7: 66.297059
A8: ASAS FG 100g UP LP | B8: 87 | C8: 52 | D8: 22.5 | F8: 33.5 | G8: 34 | H8: 27 | J8: 39
A9: COXINHA ASA IQF ALM 1KG | B9: 3.4 | C9: 24.9 | E9: 14 | F9: 8.9 | J9: 12.35
A10: PONTA ASA FG PB CG | B10: 5.6 | D10: 9.8 | J10: 7.7
A11: MEIO DA ASA 40-50G LP | B11: 28 | C11: 40.5 | D11: 70.5 | E11: 33.5 | F11: 19.3 | G11: 20.5 | H11: 31 | J11: 32.9
A12: COXINHA DA ASA FG CG PCT | C12: 99.25 | D12: 204 | E12: 260.5 | F12: 158.25 | J12: 172.94444
A13: MOELA | F13: 1.9 | J13: 1.9
A14: PEITO | B14: 16.26 | C14: 11.125 | D14: 14.366667 | E14: 7.94 | F14: 24.46 | G14: 20.571429 | H14: 15.28 | J14: 16.211364
A15: FILE PEITO MET CG BDJ SE | B15: 17.3 | C15: 11.125 | D15: 14.366667 | E15: 7.94 | F15: 17.65 | G15: 15.25 | H15: 15.28 | J15: 13.6325
A16: FILE PEITO CG IQF1KG | B16: 12.1 | F16: 51.7 | G16: 52.5 | J16: 42
A17: PERNA | B17: 21.245 | C17: 18.067857 | D17: 13.0125 | E17: 13.757143 | F17: 18.617647 | G17: 19.713043 | H17: 23.594444 | J17: 18.175449
A18: COXA CG BDJ SE | B18: 34.65 | C18: 7.8 | J18: 21.225
A19: COXA SBCX LQ FG LP | B19: 4.75 | C19: 15.125 | D19: 12.333333 | E19: -5.75 | F19: 24.833333 | G19: 10.25 | H19: 21.3 | J19: 13.846154
A20: COXA SBCX S/O BDJ CG | B20: 9.5 | C20: 5.95 | D20: -3 | E20: 0.6 | F20: 16.3 | J20: 5.4666667
A21: COXA SBCX S/O FG 200-220g PB | B21: 42.8 | C21: 40.8 | E21: 54.8 | F21: 31 | G21: 20.9 | J21: 39.966667
A22: COXA SBCX S/O FG 220-240g PB | B22: 27.1 | C22: 28.85 | D22: 23.3 | E22: 22.9 | F22: 25.5 | G22: 47.325 | H22: 26.1 | J22: 30.433333
A23: COXA SBCX S/O FG 240-260g PB | B23: 7.55 | C23: 19.366667 | D23: 10.5 | E23: 10.7 | F23: 10.85 | G23: 14.375 | H23: 24.5 | J23: 14.154545
A24: COXA SBCX S/O FG 260-280g PB | B24: -5.9 | C24: 14.5 | D24: -0.85 | E24: 14.05 | F24: 24.9 | G24: 17.325 | H24: 9.6 | J24: 13.904167
A25: COXA SBCX S/O FG 280-300g PB | B25: 27.666667 | C25: 22.866667 | D25: 12 | E25: 20.65 | F25: 11.4 | G25: 33.525 | H25: 40.666667 | J25: 24.343478
A26: OSTRINHA CG PCT 700G SWIFT | C26: 5.1 | E26: 1.2 | F26: 0.3 | G26: -26.1 | J26: -3.7363636
A27: SOBRECOXA CG BDJ SE | B27: 23.8 | C27: 2.4666667 | G27: 7 | J27: 11.6
A28: COXA SBCX S/O 200g FG UP PB | B28: 39.1 | C28: 37.2 | D28: 17.1 | H28: 19.5 | J28: 26
A29: FILE DE SOBRECOXA IQF | C29: 11.3 | H29: 22.2 | J29: 16.75
A30: COXA SBCX S/O FG 180-200g PB | D30: 53.1 | E30: 32.6 | J30: 39.433333
A31: SOBRECOXA IQF ALM 1KG | F31: 23.9 | J31: 23.9
A32: COXA SBCX S/O FG 200g UP PB | C32: 47.4 | J32: 47.4
A33: SASSAMI | B33: 7.05 | D33: 7.2 | E33: 16.3 | G33: 17.966667 | H33: 2 | I33: 1.8 | J33: 10.5
A34: FILEZINHO FRANGO IQF ALM SE | E34: 16.3 | G34: 17.966667 | I34: 1.8 | J34: 14.716667
A35: FILEZINHO PEITO CG BDJ SE | B35: 7.05 | D35: 11 | H35: 2 | J35: 7.62
A36: FILEZINHO FRANGO IQF ALM | D36: -0.4 | J36: -0.4
A37: CARTILAGEM PEITO | F37: -46.7 | G37: -1 | J37: -23.85
A38: CARTILAGEM PEITO FG PB | F38: -46.7 | G38: -1 | J38: -23.85
A39: CARTILAGEM PERNA | G39: 3.3 | J39: 3.3
A40: CARTILAGEM JOELHO FG PB | G40: 3.3 | J40: 3.3

Sheet Tabela Sobrepeso Mês
A5: Média de Desvio | B5: Rótulos de Coluna
A6: FAMÍLIA | B6: JUL | C6: AGO | D6: SET | E6: OUT
A7: ASA | C7: 21.394737 | D7: 21.209859 | E7: 66.297059
A8: ASAS FG 100g UP LP | C8: 38.74 | D8: -2.07 | E8: 39
A9: COXINHA ASA IQF ALM 1KG | C9: -8.1 | D9: 21.025 | E9: 12.35
A10: MEIO ASA CG BDJ SE | C10: 0.6
A11: MEIO DA ASA IQF | C11: 8
A12: MEIO DE ASA 2,5KG IQF | C12: -10.15 | D12: 25.56
A13: PONTA ASA FG PB CG | C13: 11.56 | D13: 7.9954545 | E13: 7.7
A14: MEIO DA ASA 40-50G LP | C14: 33 | D14: 36.464286 | E14: 32.9
A15: COXINHA DA ASA FG CG PCT | C15: 138.5 | D15: 144.56667 | E15: 172.94444
A16: COXINHA ASA IQF ALM SE | C16: 15.8 | D16: 5.28
A17: MOELA | C17: 4.7428571 | D17: 1.2428571 | E17: 1.9
A18: PEITO | B18: 17.6 | C18: 20.179268 | D18: 15.989888 | E18: 16.211364
A19: PERNA | C19: 25.795532 | D19: 20.146359 | E19: 18.175449
A20: COXA CG BDJ SE | C20: 6.3551724 | D20: 6.2666667 | E20: 21.225
A21: COXA SBCX LQ FG LP | C21: 50.584783 | D21: 22.433654 | E21: 13.846154
A22: COXA SBCX S/O BDJ CG | C22: 8.4809524 | D22: 7.44375 | E22: 5.4666667
A23: COXA SBCX S/O FG 200-220g PB | C23: 25.7 | D23: 32.651515 | E23: 39.966667
A24: COXA SBCX S/O FG 220-240g PB | C24: 44.164706 | D24: 34.703846 | E24: 30.433333
A25: COXA SBCX S/O FG 240-260g PB | C25: 21.25 | D25: 12.24717 | E25: 14.154545
A26: COXA SBCX S/O FG 260-280g PB | C26: 24.819231 | D26: 24.413462 | E26: 13.904167
A27: COXA SBCX S/O FG 280-300g PB | C27: 31.328 | D27: 23.758696 | E27: 24.343478
A28: COXA SEM PELE IQF 1KG | C28: 20.9 | D28: 15.05
A29: OSTRINHA CG PCT 700G SWIFT | C29: 0.7 | D29: 0.74285714 | E29: -3.7363636
A30: SOBRECOXA CG BDJ SE | C30: 9.1985714 | D30: 7.3285714 | E30: 11.6
A31: COXA SBCX S/O CG MP | C31: 82 | D31: 14.857143
A32: COXA SBCX S/O 200g FG UP PB | D32: 34.443333 | E32: 26
A33: SBCOXA SEM PELE IQF 1KG | D33: 23.5
A34: FILE DE SOBRECOXA IQF | D34: 11.533333 | E34: 16.75
A35: COXA SBCX S/O FG 180-200g PB | D35: 23.645455 | E35: 39.433333
A36: Turno 2 | D36: 23.645455 | E36: 39.433333
A37: SOBRECOXA FG RF PCT | D37: 168.5
A38: Turno 2 | D38: 168.5
A39: SOBRECOXA IQF ALM 1KG | D39: 24.76 | E39: 23.9
A40: Turno 1 | D40: 21.5
A41: Turno 2 | D41: 25.575 | E41: 23.9
A42: COXA SBCX S/O FG 200g UP PB | D42: 34.0625 | E42: 47.4
A43: Turno 1 | D43: 39.3 | E43: 47.4
A44: Turno 2 | D44: 28.825
...

Sheet Coleta
A1: Data Corrigida | B1: Mês | C1: ID | D1: Data e Hora | E1: Data recebimento | F1: Usuário | G1: Data e Hora2 | H1: Turno | I1: Agente de Monitoramento | J1: SKU | K1: Peso 1 | L1: Peso 2 | M1: Peso 3 | N1: Peso 4 | O1: Peso 5 | P1: Peso 6 | Q1: Peso 7 | R1: Peso 8 | S1: Peso 9 | T1: Peso 10 | U1: Média | V1: Média (Comentário) | W1: Colunas1 | X1: Tempo de resposta | Y1: Meta | Z1: % Sobrepeso | AA1: Desvio | AB1: Item | AC1: Família
A2: =INT(Tabela1[[#This Row],[Data e Hora2]]) -> 46233 | B2: =UPPER(TEXT(Tabela1[[#This Row],[Data Corrigida]],"MMM")) -> JUL | C2: 6a707861ec887be342f966e3 | D2: 30/07/2026 17:10:33 | E2: 03/08/2026 08:15:45 | F2: Ranieli | G2: 30/07/2026 | H2: Turno 2 | I2: RANIELI MARIA MASQUIETI DOURADO | J2: 15105 | K2: 1020 | L2: 1035 | M2: 1048 | N2: 995 | O2: 1003 | P2: 1038 | Q2: 1027 | R2: 1028 | S2: 1025 | T2: 957 | U2: 1017.6 | W2: assinatura | X2: 382 | Y2: =VLOOKUP(Tabela1[[#This Row],[SKU]],SKU!A:D,4,0) -> 1000 | Z2: =IFERROR((Tabela1[[#This Row],[Média]]-Tabela1[[#This Row],[Meta]])/Tabela1[[#This Row],[Meta]],"") -> 0.0176 | AA2: =Tabela1[[#This Row],[Média]]-Tabela1[[#This Row],[Meta]] -> 17.6 | AB2: =VLOOKUP(Tabela1[[#This Row],[SKU]],SKU!A:B,2,0) -> FILE PEITO MET CG BDJ SE | AC2: =VLOOKUP(Tabela1[[#This Row],[SKU]],SKU!A:C,3,0) -> PEITO
A3: =INT(Tabela1[[#This Row],[Data e Hora2]]) -> 46237 | B3: =UPPER(TEXT(Tabela1[[#This Row],[Data Corrigida]],"MMM")) -> AGO | C3: 6a71180b0aa978fc27edf554 | D3: 03/08/2026 19:26:04 | E3: 03/08/2026 19:36:59 | F3: - - | G3: 03/08/2026 | H3: Turno 2 | I3: JULIANE GOMES NOVAIS | J3: 209009 | K3: 1014 | L3: 1009 | M3: 1000 | N3: 1037 | O3: 1051 | P3: 1010 | Q3: 1019 | R3: 1012 | S3: 1000 | T3: 1007 | U3: 1015.9 | W3: assinatura | X3: 627 | Y3: =VLOOKUP(Tabela1[[#This Row],[SKU]],SKU!A:D,4,0) -> 1000 | Z3: =IFERROR((Tabela1[[#This Row],[Média]]-Tabela1[[#This Row],[Meta]])/Tabela1[[#This Row],[Meta]],"") -> 0.0159 | AA3: =Tabela1[[#This Row],[Média]]-Tabela1[[#This Row],[Meta]] -> 15.9 | AB3: =VLOOKUP(Tabela1[[#This Row],[SKU]],SKU!A:B,2,0) -> COXA SEM PELE IQF 1KG | AC3: =VLOOKUP(Tabela1[[#This Row],[SKU]],SKU!A:C,3,0) -> PERNA
A4: =INT(Tabela1[[#This Row],[Data e Hora2]]) -> 46238 | B4: =UPPER(TEXT(Tabela1[[#This Row],[Data Corrigida]],"MMM")) -> AGO | C4: 6a7299a076deefbbdc48e79a | D4: 04/08/2026 22:57:14 | E4: 04/08/2026 23:02:08 | F4: - - | G4: 04/08/2026 | H4: Turno 2 | I4: JULIANE GOMES NOVAIS | J4: 197734 | K4: 1000 | L4: 1006 | M4: 999 | N4: 1010 | O4: 1063 | P4: 1004 | Q4: 1008 | R4: 1013 | S4: 997 | T4: 1001 | U4: 1010.1 | W4: assinatura | X4: 292 | Y4: =VLOOKUP(Tabela1[[#This Row],[SKU]],SKU!A:D,4,0) -> 1000 | Z4: =IFERROR((Tabela1[[#This Row],[Média]]-Tabela1[[#This Row],[Meta]])/Tabela1[[#This Row],[Meta]],"") -> 0.0101 | AA4: =Tabela1[[#This Row],[Média]]-Tabela1[[#This Row],[Meta]] -> 10.1 | AB4: =VLOOKUP(Tabela1[[#This Row],[SKU]],SKU!A:B,2,0) -> FILEZINHO FRANGO IQF ALM SE | AC4: =VLOOKUP(Tabela1[[#This Row],[SKU]],SKU!A:C,3,0) -> SASSAMI
A5: =INT(Tabela1[[#This Row],[Data e Hora2]]) -> 46239 | B5: =UPPER(TEXT(Tabela1[[#This Row],[Data Corrigida]],"MMM")) -> AGO | C5: 6a739f5ba971cc45da77df15 | D5: 05/08/2026 16:23:50 | E5: 05/08/2026 17:38:51 | F5: - - | G5: 05/08/2026 | H5: Turno 2 | I5: RANIELI MARIA MASQUIETI DOURADO | J5: 40762 | K5: 10045 | L5: 10080 | M5: 10010 | N5: 10035 | O5: 9975 | P5: 10090 | Q5: 9980 | R5: 10005 | S5: 10065 | T5: 9970 | U5: 10025.5 | W5: assinatura | X5: 4451 | Y5: =VLOOKUP(Tabela1[[#This Row],[SKU]],SKU!A:D,4,0) -> 10000 | Z5: =IFERROR((Tabela1[[#This Row],[Média]]-Tabela1[[#This Row],[Meta]])/Tabela1[[#This Row],[Meta]],"") -> 0.00255 | AA5: =Tabela1[[#This Row],[Média]]-Tabela1[[#This Row],[Meta]] -> 25.5 | AB5: =VLOOKUP(Tabela1[[#This Row],[SKU]],SKU!A:B,2,0) -> COXA SBCX LQ FG LP | AC5: =VLOOKUP(Tabela1[[#This Row],[SKU]],SKU!A:C,3,0) -> PERNA
A6: =INT(Tabela1[[#This Row],[Data e Hora2]]) -> 46239 | B6: =UPPER(TEXT(Tabela1[[#This Row],[Data Corrigida]],"MMM")) -> AGO | C6: 6a73a4a0e24bea36d87cf4ab | D6: 05/08/2026 17:55:40 | E6: 05/08/2026 18:01:20 | F6: - - | G6: 05/08/2026 | H6: Turno 2 | I6: JOSEFA KELY NUNES DE SOUSA | J6: 15105 | K6: 1004 | L6: 1015 | M6: 1004 | N6: 1009 | O6: 1012 | P6: 1008 | Q6: 1023 | R6: 1011 | S6: 1024 | T6: 1011 | U6: 1012.1 | W6: assinatura | X6: 338 | Y6: =VLOOKUP(Tabela1[[#This Row],[SKU]],SKU!A:D,4,0) -> 1000 | Z6: =IFERROR((Tabela1[[#This Row],[Média]]-Tabela1[[#This Row],[Meta]])/Tabela1[[#This Row],[Meta]],"") -> 0.0121 | AA6: =Tabela1[[#This Row],[Média]]-Tabela1[[#This Row],[Meta]] -> 12.1 | AB6: =VLOOKUP(Tabela1[[#This Row],[SKU]],SKU!A:B,2,0) -> FILE PEITO MET CG BDJ SE | AC6: =VLOOKUP(Tabela1[[#This Row],[SKU]],SKU!A:C,3,0) -> PEITO
A7: =INT(Tabela1[[#This Row],[Data e Hora2]]) -> 46239 | B7: =UPPER(TEXT(Tabela1[[#This Row],[Data Corrigida]],"MMM")) -> AGO | C7: 6a73a7f2a3e210342a26a79a | D7: 05/08/2026 18:01:42 | E7: 05/08/2026 18:15:30 | F7: - - | G7: 05/08/2026 | H7: Turno 2 | I7: JOSEFA KELY NUNES DE SOUSA | J7: 42854 | K7: 2082 | M7: 2082 | N7: 2085 | O7: 2069 | P7: 2003 | Q7: 2151 | R7: 2084 | S7: 2155 | T7: 2099 | U7: 2090 | W7: assinatura | X7: 826 | Y7: =VLOOKUP(Tabela1[[#This Row],[SKU]],SKU!A:D,4,0) -> 2080 | Z7: =IFERROR((Tabela1[[#This Row],[Média]]-Tabela1[[#This Row],[Meta]])/Tabela1[[#This Row],[Meta]],"") -> 0.0048076923 | AA7: =Tabela1[[#This Row],[Média]]-Tabela1[[#This Row],[Meta]] -> 10 | AB7: =VLOOKUP(Tabela1[[#This Row],[SKU]],SKU!A:B,2,0) -> COXA SBCX S/O FG 260-280g PB | AC7: =VLOOKUP(Tabela1[[#This Row],[SKU]],SKU!A:C,3,0) -> PERNA
A8: =INT(Tabela1[[#This Row],[Data e Hora2]]) -> 46239 | B8: =UPPER(TEXT(Tabela1[[#This Row],[Data Corrigida]],"MMM")) -> AGO | C8: 6a73a9177d11d89e2f351df7 | D8: 05/08/2026 18:15:34 | E8: 05/08/2026 18:20:23 | F8: - - | G8: 05/08/2026 | H8: Turno 2 | I8: JOSEFA KELY NUNES DE SOUSA | J8: 42862 | K8: 2019 | L8: 2008 | M8: 1993 | N8: 2017 | O8: 2003 | P8: 2044 | Q8: 2009 | R8: 2017 | S8: 2023 | T8: 2025 | U8: 2015.8 | W8: assinatura | X8: 288 | Y8: =VLOOKUP(Tabela1[[#This Row],[SKU]],SKU!A:D,4,0) -> 2000 | Z8: =IFERROR((Tabela1[[#This Row],[Média]]-Tabela1[[#This Row],[Meta]])/Tabela1[[#This Row],[Meta]],"") -> 0.0079 | AA8: =Tabela1[[#This Row],[Média]]-Tabela1[[#This Row],[Meta]] -> 15.8 | AB8: =VLOOKUP(Tabela1[[#This Row],[SKU]],SKU!A:B,2,0) -> COXA SBCX S/O FG 280-300g PB | AC8: =VLOOKUP(Tabela1[[#This Row],[SKU]],SKU!A:C,3,0) -> PERNA
A9: =INT(Tabela1[[#This Row],[Data e Hora2]]) -> 46239 | B9: =UPPER(TEXT(Tabela1[[#This Row],[Data Corrigida]],"MMM")) -> AGO | C9: 6a73aa3f9a3f99d409c1af0c | D9: 05/08/2026 18:20:24 | E9: 05/08/2026 18:25:19 | F9: - - | G9: 05/08/2026 | H9: Turno 2 | I9: JOSEFA KELY NUNES DE SOUSA | J9: 42846 | K9: 2025 | L9: 2039 | M9: 2002 | N9: 2199 | O9: 2128 | P9: 1994 | Q9: 2032 | R9: 1981 | S9: 2015 | T9: 2016 | U9: 2043.1 | W9: assinatura | X9: 293 | Y9: =VLOOKUP(Tabela1[[#This Row],[SKU]],SKU!A:D,4,0) -> 2000 | Z9: =IFERROR((Tabela1[[#This Row],[Média]]-Tabela1[[#This Row],[Meta]])/Tabela1[[#This Row],[Meta]],"") -> 0.02155 | AA9: =Tabela1[[#This Row],[Média]]-Tabela1[[#This Row],[Meta]] -> 43.1 | AB9: =VLOOKUP(Tabela1[[#This Row],[SKU]],SKU!A:B,2,0) -> COXA SBCX S/O FG 240-260g PB | AC9: =VLOOKUP(Tabela1[[#This Row],[SKU]],SKU!A:C,3,0) -> PERNA
A10: =INT(Tabela1[[#This Row],[Data e Hora2]]) -> 46239 | B10: =UPPER(TEXT(Tabela1[[#This Row],[Data Corrigida]],"MMM")) -> AGO | C10: 6a73aba2ef0d98d29d5b81b3 | D10: 05/08/2026 18:25:21 | E10: 05/08/2026 18:31:14 | F10: - - | G10: 05/08/2026 | H10: Turno 2 | I10: JOSEFA KELY NUNES DE SOUSA | J10: 42838 | K10: 2030 | L10: 1997 | M10: 1996 | N10: 2006 | O10: 2023 | P10: 2113 | Q10: 2006 | R10: 2013 | S10: 2018 | T10: 2007 | U10: 2020.9 | W10: assinatura | X10: 351 | Y10: =VLOOKUP(Tabela1[[#This Row],[SKU]],SKU!A:D,4,0) -> 2000 | Z10: =IFERROR((Tabela1[[#This Row],[Média]]-Tabela1[[#This Row],[Meta]])/Tabela1[[#This Row],[Meta]],"") -> 0.01045 | AA10: =Tabela1[[#This Row],[Média]]-Tabela1[[#This Row],[Meta]] -> 20.9 | AB10: =VLOOKUP(Tabela1[[#This Row],[SKU]],SKU!A:B,2,0) -> COXA SBCX S/O FG 220-240g PB | AC10: =VLOOKUP(Tabela1[[#This Row],[SKU]],SKU!A:C,3,0) -> PERNA
A11: =INT(Tabela1[[#This Row],[Data e Hora2]]) -> 46239 | B11: =UPPER(TEXT(Tabela1[[#This Row],[Data Corrigida]],"MMM")) -> AGO | C11: 6a73acfe76deefbbdc4bb386 | D11: 05/08/2026 18:31:15 | E11: 05/08/2026 18:37:02 | F11: - - | G11: 05/08/2026 | H11: Turno 2 | I11: JOSEFA KELY NUNES DE SOUSA | J11: 13188 | K11: 1006 | L11: 1016 | M11: 1012 | N11: 1025 | O11: 1025 | P11: 1012 | Q11: 1001 | R11: 1017 | S11: 1024 | T11: 1017 | U11: 1015.5 | W11: assinatura | X11: 344 | Y11: =VLOOKUP(Tabela1[[#This Row],[SKU]],SKU!A:D,4,0) -> 1000 | Z11: =IFERROR((Tabela1[[#This Row],[Média]]-Tabela1[[#This Row],[Meta]])/Tabela1[[#This Row],[Meta]],"") -> 0.0155 | AA11: =Tabela1[[#This Row],[Média]]-Tabela1[[#This Row],[Meta]] -> 15.5 | AB11: =VLOOKUP(Tabela1[[#This Row],[SKU]],SKU!A:B,2,0) -> SOBRECOXA CG BDJ SE | AC11: =VLOOKUP(Tabela1[[#This Row],[SKU]],SKU!A:C,3,0) -> PERNA
A12: =INT(Tabela1[[#This Row],[Data e Hora2]]) -> 46239 | B12: =UPPER(TEXT(Tabela1[[#This Row],[Data Corrigida]],"MMM")) -> AGO | C12: 6a73b48c9a3f99d409c1b4d5 | D12: 05/08/2026 19:04:16 | E12: 05/08/2026 19:09:16 | F12: - - | G12: 05/08/2026 | H12: Turno 2 | I12: JULIANE GOMES NOVAIS | J12: 209009 | K12: 1026 | L12: 1005 | M12: 1011 | N12: 1046 | O12: 1010 | P12: 1049 | Q12: 1003 | R12: 1050 | S12: 1032 | T12: 1027 | U12: 1025.9 | W12: assinatura | X12: 291 | Y12: =VLOOKUP(Tabela1[[#This Row],[SKU]],SKU!A:D,4,0) -> 1000 | Z12: =IFERROR((Tabela1[[#This Row],[Média]]-Tabela1[[#This Row],[Meta]])/Tabela1[[#This Row],[Meta]],"") -> 0.0259 | AA12: =Tabela1[[#This Row],[Média]]-Tabela1[[#This Row],[Meta]] -> 25.9 | AB12: =VLOOKUP(Tabela1[[#This Row],[SKU]],SKU!A:B,2,0) -> COXA SEM PELE IQF 1KG | AC12: =VLOOKUP(Tabela1[[#This Row],[SKU]],SKU!A:C,3,0) -> PERNA
A13: =INT(Tabela1[[#This Row],[Data e Hora2]]) -> 46239 | B13: =UPPER(TEXT(Tabela1[[#This Row],[Data Corrigida]],"MMM")) -> AGO | C13: 6a73ec07e9cbec6cab797c5b | D13: 05/08/2026 22:58:57 | E13: 05/08/2026 23:05:59 | F13: - - | G13: 05/08/2026 | H13: Turno 2 | I13: JOSEFA KELY NUNES DE SOUSA | J13: 15105 | K13: 1013 | L13: 990 | M13: 1203 | N13: 1037 | O13: 1025 | P13: 1035 | Q13: 991 | R13: 1014 | S13: 1039 | T13: 1034 | U13: 1038.1 | W13: assinatura | X13: 384 | Y13: =VLOOKUP(Tabela1[[#This Row],[SKU]],SKU!A:D,4,0) -> 1000 | Z13: =IFERROR((Tabela1[[#This Row],[Média]]-Tabela1[[#This Row],[Meta]])/Tabela1[[#This Row],[Meta]],"") -> 0.0381 | AA13: =Tabela1[[#This Row],[Média]]-Tabela1[[#This Row],[Meta]] -> 38.1 | AB13: =VLOOKUP(Tabela1[[#This Row],[SKU]],SKU!A:B,2,0) -> FILE PEITO MET CG BDJ SE | AC13: =VLOOKUP(Tabela1[[#This Row],[SKU]],SKU!A:C,3,0) -> PEITO
A14: =INT(Tabela1[[#This Row],[Data e Hora2]]) -> 46239 | B14: =UPPER(TEXT(Tabela1[[#This Row],[Data Corrigida]],"MMM")) -> AGO | C14: 6a74069b20a96cfc4b4e285d | D14: 06/08/2026 00:49:36 | E14: 06/08/2026 00:59:23 | F14: - - | G14: 05/08/2026 | H14: Turno 2 | I14: JOSEFA KELY NUNES DE SOUSA | J14: 15229 | K14: 1019 | L14: 1018 | M14: 1016 | N14: 1021 | O14: 1017 | P14: 1023 | Q14: 997 | R14: 1022 | S14: 1020 | T14: 999 | U14: 1015.2 | W14: assinatura | X14: 587 | Y14: =VLOOKUP(Tabela1[[#This Row],[SKU]],SKU!A:D,4,0) -> 1000 | Z14: =IFERROR((Tabela1[[#This Row],[Média]]-Tabela1[[#This Row],[Meta]])/Tabela1[[#This Row],[Meta]],"") -> 0.0152 | AA14: =Tabela1[[#This Row],[Média]]-Tabela1[[#This Row],[Meta]] -> 15.2 | AB14: =VLOOKUP(Tabela1[[#This Row],[SKU]],SKU!A:B,2,0) -> COXA CG BDJ SE | AC14: =VLOOKUP(Tabela1[[#This Row],[SKU]],SKU!A:C,3,0) -> PERNA
A15: =INT(Tabela1[[#This Row],[Data e Hora2]]) -> 46239 | B15: =UPPER(TEXT(Tabela1[[#This Row],[Data Corrigida]],"MMM")) -> AGO | C15: 6a740886f40feae6226636ee | D15: 06/08/2026 01:00:00 | E15: 06/08/2026 01:07:34 | F15: - - | G15: 05/08/2026 | H15: Turno 2 | I15: JOSEFA KELY NUNES DE SOUSA | J15: 42846 | K15: 2055 | L15: 2071 | M15: 2048 | N15: 2070 | O15: 2018 | P15: 2003 | Q15: 2013 | R15: 2073 | S15: 2042 | T15: 2039 | U15: 2043.2 | W15: assinatura | X15: 453 | Y15: =VLOOKUP(Tabela1[[#This Row],[SKU]],SKU!A:D,4,0) -> 2000 | Z15: =IFERROR((Tabela1[[#This Row],[Média]]-Tabela1[[#This Row],[Meta]])/Tabela1[[#This Row],[Meta]],"") -> 0.0216 | AA15: =Tabela1[[#This Row],[Média]]-Tabela1[[#This Row],[Meta]] -> 43.2 | AB15: =VLOOKUP(Tabela1[[#This Row],[SKU]],SKU!A:B,2,0) -> COXA SBCX S/O FG 240-260g PB | AC15: =VLOOKUP(Tabela1[[#This Row],[SKU]],SKU!A:C,3,0) -> PERNA
A16: =INT(Tabela1[[#This Row],[Data e Hora2]]) -> 46239 | B16: =UPPER(TEXT(Tabela1[[#This Row],[Data Corrigida]],"MMM")) -> AGO | C16: 6a7409d8f40feae622663743 | D16: 06/08/2026 01:07:38 | E16: 06/08/2026 01:13:12 | F16: - - | G16: 05/08/2026 | H16: Turno 2 | I16: JOSEFA KELY NUNES DE SOUSA | J16: 42862 | K16: 2093 | L16: 2024 | M16: 2010 | N16: 1978 | O16: 1974 | P16: 2026 | Q16: 2028 | R16: 2020 | S16: 2001 | T16: 2003 | U16: 2015.7 | W16: assinatura | X16: 332 | Y16: =VLOOKUP(Tabela1[[#This Row],[SKU]],SKU!A:D,4,0) -> 2000 | Z16: =IFERROR((Tabela1[[#This Row],[Média]]-Tabela1[[#This Row],[Meta]])/Tabela1[[#This Row],[Meta]],"") -> 0.00785 | AA16: =Tabela1[[#This Row],[Média]]-Tabela1[[#This Row],[Meta]] -> 15.7 | AB16: =VLOOKUP(Tabela1[[#This Row],[SKU]],SKU!A:B,2,0) -> COXA SBCX S/O FG 280-300g PB | AC16: =VLOOKUP(Tabela1[[#This Row],[SKU]],SKU!A:C,3,0) -> PERNA
A17: =INT(Tabela1[[#This Row],[Data e Hora2]]) -> 46239 | B17: =UPPER(TEXT(Tabela1[[#This Row],[Data Corrigida]],"MMM")) -> AGO | C17: 6a740b3876deefbbdc4bdd28 | D17: 06/08/2026 01:13:16 | E17: 06/08/2026 01:19:04 | F17: - - | G17: 05/08/2026 | H17: Turno 2 | I17: JOSEFA KELY NUNES DE SOUSA | J17: 42854 | K17: 2066 | L17: 2022 | M17: 2038 | N17: 2109 | O17: 2140 | P17: 2133 | Q17: 2144 | R17: 2125 | S17: 2165 | T17: 2190 | U17: 2113.2 | W17: assinatura | X17: 347 | Y17: =VLOOKUP(Tabela1[[#This Row],[SKU]],SKU!A:D,4,0) -> 2080 | Z17: =IFERROR((Tabela1[[#This Row],[Média]]-Tabela1[[#This Row],[Meta]])/Tabela1[[#This Row],[Meta]],"") -> 0.015961538 | AA17: =Tabela1[[#This Row],[Média]]-Tabela1[[#This Row],[Meta]] -> 33.2 | AB17: =VLOOKUP(Tabela1[[#This Row],[SKU]],SKU!A:B,2,0) -> COXA SBCX S/O FG 260-280g PB | AC17: =VLOOKUP(Tabela1[[#This Row],[SKU]],SKU!A:C,3,0) -> PERNA
A18: =INT(Tabela1[[#This Row],[Data e Hora2]]) -> 46239 | B18: =UPPER(TEXT(Tabela1[[#This Row],[Data Corrigida]],"MMM")) -> AGO | C18: 6a740d80b671965c6502efd8 | D18: 06/08/2026 01:19:06 | E18: 06/08/2026 01:28:48 | F18: - - | G18: 05/08/2026 | H18: Turno 2 | I18: JOSEFA KELY NUNES DE SOUSA | J18: 42838 | K18: 2073 | L18: 1987 | M18: 2066 | N18: 2040 | O18: 2141 | P18: 2015 | Q18: 2013 | R18: 2078 | S18: 2075 | T18: 2065 | U18: 2055.3 | W18: assinatura | X18: 581 | Y18: =VLOOKUP(Tabela1[[#This Row],[SKU]],SKU!A:D,4,0) -> 2000 | Z18: =IFERROR((Tabela1[[#This Row],[Média]]-Tabela1[[#This Row],[Meta]])/Tabela1[[#This Row],[Meta]],"") -> 0.02765 | AA18: =Tabela1[[#This Row],[Média]]-Tabela1[[#This Row],[Meta]] -> 55.3 | AB18: =VLOOKUP(Tabela1[[#This Row],[SKU]],SKU!A:B,2,0) -> COXA SBCX S/O FG 220-240g PB | AC18: =VLOOKUP(Tabela1[[#This Row],[SKU]],SKU!A:C,3,0) -> PERNA
A19: =INT(Tabela1[[#This Row],[Data e Hora2]]) -> 46240 | B19: =UPPER(TEXT(Tabela1[[#This Row],[Data Corrigida]],"MMM")) -> AGO | C19: 6a74f6dc9a3f99d409cf0ade | D19: 06/08/2026 17:53:56 | E19: 06/08/2026 18:04:28 | F19: - - | G19: 06/08/2026 | H19: Turno 2 | I19: JOSEFA KELY NUNES DE SOUSA | J19: 15105 | K19: 1007 | L19: 998 | M19: 992 | N19: 1040 | O19: 1035 | P19: 1049 | Q19: 1022 | R19: 1009 | S19: 1005 | T19: 1018 | U19: 1017.5 | W19: assinatura | X19: 622 | Y19: =VLOOKUP(Tabela1[[#This Row],[SKU]],SKU!A:D,4,0) -> 1000 | Z19: =IFERROR((Tabela1[[#This Row],[Média]]-Tabela1[[#This Row],[Meta]])/Tabela1[[#This Row],[Meta]],"") -> 0.0175 | AA19: =Tabela1[[#This Row],[Média]]-Tabela1[[#This Row],[Meta]] -> 17.5 | AB19: =VLOOKUP(Tabela1[[#This Row],[SKU]],SKU!A:B,2,0) -> FILE PEITO MET CG BDJ SE | AC19: =VLOOKUP(Tabela1[[#This Row],[SKU]],SKU!A:C,3,0) -> PEITO
... A31: =INT(Tabela1[[#This Row],[Data e Hora2]]) -> 46240 | B31: =UPPER(TEXT(Tabela1[[#This Row],[Data Corrigida]],"MMM")) -> AGO | C31: 6a7554cf7d11d89e2f42171d | D31: 07/08/2026 00:36:04 | E31: 07/08/2026 00:45:19 | F31: - - | G31: 06/08/2026 | H31: Turno 2 | I31: JOSEFA KELY NUNES DE SOUSA | J31: 792799 | K31: 15060 | L31: 15080 | M31: 15055 | N31: 15090 | O31: 15065 | P31: 15035 | Q31: 15020 | R31: 15000 | S31: 15055 | T31: 15000 | U31: 15046 | W31: assinatura | X31: 554 | Y31: =VLOOKUP(Tabela1[[#This Row],[SKU]],SKU!A:D,4,0) -> 15000 | Z31: =IFERROR((Tabela1[[#This Row],[Média]]-Tabela1[[#This Row],[Meta]])/Tabela1[[#This Row],[Meta]],"") -> 0.0030666667 | AA31: =Tabela1[[#This Row],[Média]]-Tabela1[[#This Row],[Meta]] -> 46 | AB31: =VLOOKUP(Tabela1[[#This Row],[SKU]],SKU!A:B,2,0) -> ASAS FG 100g UP LP | AC31: =VLOOKUP(Tabela1[[#This Row],[SKU]],SKU!A:C,3,0) -> ASA
A32: =INT(Tabela1[[#This Row],[Data e Hora2]]) -> 46240 | B32: =UPPER(TEXT(Tabela1[[#This Row],[Data Corrigida]],"MMM")) -> AGO | C32: 6a7557307d11d89e2f421791 | D32: 07/08/2026 00:45:21 | E32: 07/08/2026 00:55:28 | F32: - - | G32: 06/08/2026 | H32: Turno 2 | J32: 992093 | K32: 5008 | L32: 5002 | M32: 5022 | N32: 5008 | O32: 5005 | P32: 5008 | Q32: 5012 | R32: 5009 | S32: 5002 | T32: 5001 | U32: 5007.7 | W32: assinatura | X32: 606 | Y32: =VLOOKUP(Tabela1[[#This Row],[SKU]],SKU!A:D,4,0) -> 5000 | Z32: =IFERROR((Tabela1[[#This Row],[Média]]-Tabela1[[#This Row],[Meta]])/Tabela1[[#This Row],[Meta]],"") -> 0.00154 | AA32: =Tabela1[[#This Row],[Média]]-Tabela1[[#This Row],[Meta]] -> 7.7 | AB32: =VLOOKUP(Tabela1[[#This Row],[SKU]],SKU!A:B,2,0) -> PONTA ASA FG PB CG | AC32: =VLOOKUP(Tabela1[[#This Row],[SKU]],SKU!A:C,3,0) -> ASA
A33: =INT(Tabela1[[#This Row],[Data e Hora2]]) -> 46241 | B33: =UPPER(TEXT(Tabela1[[#This Row],[Data Corrigida]],"MMM")) -> AGO | C33: 6a79aef44b165449d5bfd7b9 | D33: 07/08/2026 17:41:25 | E33: 10/08/2026 07:59:00 | F33: Ranieli | G33: 07/08/2026 | H33: Turno 2 | I33: JOSEFA KELY NUNES DE SOUSA | J33: 42820 | K33: 1999 | L33: 2085 | M33: 2000 | N33: 2033 | O33: 2033 | P33: 2051 | Q33: 2023 | R33: 2016 | S33: 2035 | T33: 1989 | U33: 2026.4 | W33: assinatura | X33: 2758 | Y33: =VLOOKUP(Tabela1[[#This Row],[SKU]],SKU!A:D,4,0) -> 2000 | Z33: =IFERROR((Tabela1[[#This Row],[Média]]-Tabela1[[#This Row],[Meta]])/Tabela1[[#This Row],[Meta]],"") -> 0.0132 | AA33: =Tabela1[[#This Row],[Média]]-Tabela1[[#This Row],[Meta]] -> 26.4 | AB33: =VLOOKUP(Tabela1[[#This Row],[SKU]],SKU!A:B,2,0) -> COXA SBCX S/O FG 200-220g PB | AC33: =VLOOKUP(Tabela1[[#This Row],[SKU]],SKU!A:C,3,0) -> PERNA
A34: =INT(Tabela1[[#This Row],[Data e Hora2]]) -> 46241 | B34: =UPPER(TEXT(Tabela1[[#This Row],[Data Corrigida]],"MMM")) -> AGO | C34: 6a79aef54b165449d5bfd7bf | D34: 07/08/2026 18:27:25 | E34: 10/08/2026 07:59:01 | F34: Ranieli | G34: 07/08/2026 | H34: Turno 2 | I34: JOSEFA KELY NUNES DE SOUSA | J34: 42854 | K34: 2002 | L34: 2119 | M34: 2151 | N34: 2100 | O34: 2099 | P34: 2110 | Q34: 2117 | R34: 2079 | S34: 2139 | T34: 2115 | U34: 2103.1 | X34: 181 | Y34: =VLOOKUP(Tabela1[[#This Row],[SKU]],SKU!A:D,4,0) -> 2080 | Z34: =IFERROR((Tabela1[[#This Row],[Média]]-Tabela1[[#This Row],[Meta]])/Tabela1[[#This Row],[Meta]],"") -> 0.011105769 | AA34: =Tabela1[[#This Row],[Média]]-Tabela1[[#This Row],[Meta]] -> 23.1 | AB34: =VLOOKUP(Tabela1[[#This Row],[SKU]],SKU!A:B,2,0) -> COXA SBCX S/O FG 260-280g PB | AC34: =VLOOKUP(Tabela1[[#This Row],[SKU]],SKU!A:C,3,0) -> PERNA
A35: =INT(Tabela1[[#This Row],[Data e Hora2]]) -> 46241 | B35: =UPPER(TEXT(Tabela1[[#This Row],[Data Corrigida]],"MMM")) -> AGO | C35: 6a79aef54b165449d5bfd7c5 | D35: 07/08/2026 18:30:28 | E35: 10/08/2026 07:59:01 | F35: Ranieli | G35: 07/08/2026 | H35: Turno 2 | I35: JOSEFA KELY NUNES DE SOUSA | J35: 42846 | K35: 2000 | L35: 2013 | M35: 2010 | N35: 2013 | O35: 2016 | P35: 2003 | Q35: 1994 | R35: 2009 | S35: 1770 | T35: 1999 | U35: 1982.7 | W35: assinatura | X35: 233 | Y35: =VLOOKUP(Tabela1[[#This Row],[SKU]],SKU!A:D,4,0) -> 2000 | Z35: =IFERROR((Tabela1[[#This Row],[Média]]-Tabela1[[#This Row],[Meta]])/Tabela1[[#This Row],[Meta]],"") -> -0.00865 | AA35: =Tabela1[[#This Row],[Média]]-Tabela1[[#This Row],[Meta]] -> -17.3 | AB35: =VLOOKUP(Tabela1[[#This Row],[SKU]],SKU!A:B,2,0) -> COXA SBCX S/O FG 240-260g PB | AC35: =VLOOKUP(Tabela1[[#This Row],[SKU]],SKU!A:C,3,0) -> PERNA
A36: =INT(Tabela1[[#This Row],[Data e Hora2]]) -> 46241 | B36: =UPPER(TEXT(Tabela1[[#This Row],[Data Corrigida]],"MMM")) -> AGO | C36: 6a79aef54b165449d5bfd7cb | D36: 07/08/2026 18:34:24 | E36: 10/08/2026 07:59:01 | F36: Ranieli | G36: 07/08/2026 | H36: Turno 2 | I36: JOSEFA KELY NUNES DE SOUSA | J36: 42862 | K36: 2016 | L36: 2009 | M36: 2057 | N36: 2040 | O36: 2059 | P36: 2001 | Q36: 2017 | R36: 2016 | S36: 2003 | T36: 2023 | U36: 2024.1 | X36: 148 | Y36: =VLOOKUP(Tabela1[[#This Row],[SKU]],SKU!A:D,4,0) -> 2000 | Z36: =IFERROR((Tabela1[[#This Row],[Média]]-Tabela1[[#This Row],[Meta]])/Tabela1[[#This Row],[Meta]],"") -> 0.01205 | AA36: =Tabela1[[#This Row],[Média]]-Tabela1[[#This Row],[Meta]] -> 24.1 | AB36: =VLOOKUP(Tabela1[[#This Row],[SKU]],SKU!A:B,2,0) -> COXA SBCX S/O FG 280-300g PB | AC36: =VLOOKUP(Tabela1[[#This Row],[SKU]],SKU!A:C,3,0) -> PERNA
A37: =INT(Tabela1[[#This Row],[Data e Hora2]]) -> 46241 | B37: =UPPER(TEXT(Tabela1[[#This Row],[Data Corrigida]],"MMM")) -> AGO | C37: 6a79aef54b165449d5bfd7d3 | D37: 07/08/2026 18:36:55 | E37: 10/08/2026 07:59:01 | F37: Ranieli | G37: 07/08/2026 | H37: Turno 2 | I37: JOSEFA KELY NUNES DE SOUSA | J37: 13188 | K37: 1014 | L37: 1020 | M37: 1023 | N37: 994 | O37: 993 | P37: 1013 | Q37: 998 | R37: 1007 | S37: 1023 | T37: 997 | U37: 1008.2 | X37: 210 | Y37: =VLOOKUP(Tabela1[[#This Row],[SKU]],SKU!A:D,4,0) -> 1000 | Z37: =IFERROR((Tabela1[[#This Row],[Média]]-Tabela1[[#This Row],[Meta]])/Tabela1[[#This Row],[Meta]],"") -> 0.0082 | AA37: =Tabela1[[#This Row],[Média]]-Tabela1[[#This Row],[Meta]] -> 8.2 | AB37: =VLOOKUP(Tabela1[[#This Row],[SKU]],SKU!A:B,2,0) -> SOBRECOXA CG BDJ SE | AC37: =VLOOKUP(Tabela1[[#This Row],[SKU]],SKU!A:C,3,0) -> PERNA
A38: =INT(Tabela1[[#This Row],[Data e Hora2]]) -> 46241 | B38: =UPPER(TEXT(Tabela1[[#This Row],[Data Corrigida]],"MMM")) -> AGO | C38: 6a79aef54b165449d5bfd7d9 | D38: 07/08/2026 18:40:29 | E38: 10/08/2026 07:59:01 | F38: Ranieli | G38: 07/08/2026 | H38: Turno 2 | I38: JOSEFA KELY NUNES DE SOUSA | J38: 15105 | K38: 992 | L38: 998 | M38: 1011 | N38: 1018 | O38: 957 | P38: 920 | Q38: 1021 | R38: 1020 | S38: 1060 | T38: 1014 | U38: 1001.1 | W38: assinatura | X38: 533 | Y38: =VLOOKUP(Tabela1[[#This Row],[SKU]],SKU!A:D,4,0) -> 1000 | Z38: =IFERROR((Tabela1[[#This Row],[Média]]-Tabela1[[#This Row],[Meta]])/Tabela1[[#This Row],[Meta]],"") -> 0.0011 | AA38: =Tabela1[[#This Row],[Média]]-Tabela1[[#This Row],[Meta]] -> 1.1 | AB38: =VLOOKUP(Tabela1[[#This Row],[SKU]],SKU!A:B,2,0) -> FILE PEITO MET CG BDJ SE | AC38: =VLOOKUP(Tabela1[[#This Row],[SKU]],SKU!A:C,3,0) -> PEITO
A39: =INT(Tabela1[[#This Row],[Data e Hora2]]) -> 46241 | B39: =UPPER(TEXT(Tabela1[[#This Row],[Data Corrigida]],"MMM")) -> AGO | C39: 6a79aef54b165449d5bfd7df | D39: 07/08/2026 18:49:24 | E39: 10/08/2026 07:59:01 | F39: Ranieli | G39: 07/08/2026 | H39: Turno 2 | I39: JOSEFA KELY NUNES DE SOUSA | J39: 992093 | K39: 5014 | L39: 5015 | M39: 5014 | N39: 5021 | O39: 5014 | P39: 5015 | Q39: 5017 | R39: 5010 | S39: 5014 | T39: 5014 | U39: 5014.8 | W39: assinatura | X39: 465 | Y39: =VLOOKUP(Tabela1[[#This Row],[SKU]],SKU!A:D,4,0) -> 5000 | Z39: =IFERROR((Tabela1[[#This Row],[Média]]-Tabela1[[#This Row],[Meta]])/Tabela1[[#This Row],[Meta]],"") -> 0.00296 | AA39: =Tabela1[[#This Row],[Média]]-Tabela1[[#This Row],[Meta]] -> 14.8 | AB39: =VLOOKUP(Tabela1[[#This Row],[SKU]],SKU!A:B,2,0) -> PONTA ASA FG PB CG | AC39: =VLOOKUP(Tabela1[[#This Row],[SKU]],SKU!A:C,3,0) -> ASA
A40: =INT(Tabela1[[#This Row],[Data e Hora2]]) -> 46241 | B40: =UPPER(TEXT(Tabela1[[#This Row],[Data Corrigida]],"MMM")) -> AGO | C40: 6a79aef54b165449d5bfd7fd | D40: 08/08/2026 00:28:19 | E40: 10/08/2026 07:59:01 | F40: Ranieli | G40: 07/08/2026 | H40: Turno 2 | I40: JOSEFA KELY NUNES DE SOUSA | J40: 15105 | K40: 1009 | L40: 1025 | M40: 1003 | N40: 1035 | O40: 1029 | P40: 1004 | Q40: 1000 | R40: 1004 | S40: 1013 | T40: 1007 | U40: 1012.9 | W40: assinatura | X40: 440 | Y40: =VLOOKUP(Tabela1[[#This Row],[SKU]],SKU!A:D,4,0) -> 1000 | Z40: =IFERROR((Tabela1[[#This Row],[Média]]-Tabela1[[#This Row],[Meta]])/Tabela1[[#This Row],[Meta]],"") -> 0.0129 | AA40: =Tabela1[[#This Row],[Média]]-Tabela1[[#This Row],[Meta]] -> 12.9 | AB40: =VLOOKUP(Tabela1[[#This Row],[SKU]],SKU!A:B,2,0) -> FILE PEITO MET CG BDJ SE | AC40: =VLOOKUP(Tabela1[[#This Row],[SKU]],SKU!A:C,3,0) -> PEITO
A41: =INT(Tabela1[[#This Row],[Data e Hora2]]) -> 46241 | B41: =UPPER(TEXT(Tabela1[[#This Row],[Data Corrigida]],"MMM")) -> AGO | C41: 6a79aef54b165449d5bfd803 | D41: 08/08/2026 00:35:45 | E41: 10/08/2026 07:59:01 | F41: Ranieli | G41: 07/08/2026 | H41: Turno 2 | I41: JOSEFA KELY NUNES DE SOUSA | J41: 13188 | K41: 1014 | L41: 1019 | M41: 1005 | N41: 994 | O41: 1024 | P41: 1022 | Q41: 1027 | R41: 1016 | S41: 1009 | T41: 1038 | U41: 1016.8 | W41: assinatura | X41: 574 | Y41: =VLOOKUP(Tabela1[[#This Row],[SKU]],SKU!A:D,4,0) -> 1000 | Z41: =IFERROR((Tabela1[[#This Row],[Média]]-Tabela1[[#This Row],[Meta]])/Tabela1[[#This Row],[Meta]],"") -> 0.0168 | AA41: =Tabela1[[#This Row],[Média]]-Tabela1[[#This Row],[Meta]] -> 16.8 | AB41: =VLOOKUP(Tabela1[[#This Row],[SKU]],SKU!A:B,2,0) -> SOBRECOXA CG BDJ SE | AC41: =VLOOKUP(Tabela1[[#This Row],[SKU]],SKU!A:C,3,0) -> PERNA
A42: =INT(Tabela1[[#This Row],[Data e Hora2]]) -> 46241 | B42: =UPPER(TEXT(Tabela1[[#This Row],[Data Corrigida]],"MMM")) -> AGO | C42: 6a79aef54b165449d5bfd809 | D42: 08/08/2026 00:45:27 | E42: 10/08/2026 07:59:01 | F42: Ranieli | G42: 07/08/2026 | H42: Turno 2 | J42: 40762 | K42: 10070 | L42: 9885 | M42: 9875 | N42: 9955 | O42: 9985 | P42: 9965 | Q42: 9885 | R42: 10060 | S42: 10010 | T42: 9885 | U42: 9957.5 | X42: 472 | Y42: =VLOOKUP(Tabela1[[#This Row],[SKU]],SKU!A:D,4,0) -> 10000 | Z42: =IFERROR((Tabela1[[#This Row],[Média]]-Tabela1[[#This Row],[Meta]])/Tabela1[[#This Row],[Meta]],"") -> -0.00425 | AA42: =Tabela1[[#This Row],[Média]]-Tabela1[[#This Row],[Meta]] -> -42.5 | AB42: =VLOOKUP(Tabela1[[#This Row],[SKU]],SKU!A:B,2,0) -> COXA SBCX LQ FG LP | AC42: =VLOOKUP(Tabela1[[#This Row],[SKU]],SKU!A:C,3,0) -> PERNA
A43: =INT(Tabela1[[#This Row],[Data e Hora2]]) -> 46244 | B43: =UPPER(TEXT(Tabela1[[#This Row],[Data Corrigida]],"MMM")) -> AGO | C43: 6a7ab139f77da7ef00271bbb | D43: 10/08/2026 17:42:33 | E43: 11/08/2026 02:20:57 | F43: Ranieli | G43: 10/08/2026 | H43: Turno 2 | I43: JOSEFA KELY NUNES DE SOUSA | J43: 42846 | K43: 2010 | L43: 2019 | M43: 2010 | N43: 2021 | O43: 2005 | P43: 2062 | Q43: 2005 | R43: 2104 | S43: 2015 | T43: 1997 | U43: 2024.8 | W43: assinatura | X43: 299 | Y43: =VLOOKUP(Tabela1[[#This Row],[SKU]],SKU!A:D,4,0) -> 2000 | Z43: =IFERROR((Tabela1[[#This Row],[Média]]-Tabela1[[#This Row],[Meta]])/Tabela1[[#This Row],[Meta]],"") -> 0.0124 | AA43: =Tabela1[[#This Row],[Média]]-Tabela1[[#This Row],[Meta]] -> 24.8 | AB43: =VLOOKUP(Tabela1[[#This Row],[SKU]],SKU!A:B,2,0) -> COXA SBCX S/O FG 240-260g PB | AC43: =VLOOKUP(Tabela1[[#This Row],[SKU]],SKU!A:C,3,0) -> PERNA
A44: =INT(Tabela1[[#This Row],[Data e Hora2]]) -> 46244 | B44: =UPPER(TEXT(Tabela1[[#This Row],[Data Corrigida]],"MMM")) -> AGO | C44: 6a7ab139f77da7ef00271bc1 | D44: 10/08/2026 17:47:34 | E44: 11/08/2026 02:20:57 | F44: Ranieli | G44: 10/08/2026 | H44: Turno 2 | I44: JOSEFA KELY NUNES DE SOUSA | J44: 42838 | K44: 2025 | L44: 2043 | M44: 2034 | N44: 2046 | O44: 2032 | P44: 2017 | Q44: 2031 | R44: 2031 | S44: 2082 | T44: 2140 | U44: 2048.1 | X44: 153 | Y44: =VLOOKUP(Tabela1[[#This Row],[SKU]],SKU!A:D,4,0) -> 2000 | Z44: =IFERROR((Tabela1[[#This Row],[Média]]-Tabela1[[#This Row],[Meta]])/Tabela1[[#This Row],[Meta]],"") -> 0.02405 | AA44: =Tabela1[[#This Row],[Média]]-Tabela1[[#This Row],[Meta]] -> 48.1 | AB44: =VLOOKUP(Tabela1[[#This Row],[SKU]],SKU!A:B,2,0) -> COXA SBCX S/O FG 220-240g PB | AC44: =VLOOKUP(Tabela1[[#This Row],[SKU]],SKU!A:C,3,0) -> PERNA
A45: =INT(Tabela1[[#This Row],[Data e Hora2]]) -> 46244 | B45: =UPPER(TEXT(Tabela1[[#This Row],[Data Corrigida]],"MMM")) -> AGO | C45: 6a7ab139f77da7ef00271bc7 | D45: 10/08/2026 17:50:09 | E45: 11/08/2026 02:20:57 | F45: Ranieli | G45: 10/08/2026 | H45: Turno 2 | I45: JOSEFA KELY NUNES DE SOUSA | J45: 42854 | K45: 2098 | L45: 2133 | M45: 2114 | N45: 2088 | O45: 2079 | P45: 2092 | Q45: 2097 | R45: 2126 | S45: 2099 | T45: 2119 | U45: 2104.5 | X45: 239 | Y45: =VLOOKUP(Tabela1[[#This Row],[SKU]],SKU!A:D,4,0) -> 2080 | Z45: =IFERROR((Tabela1[[#This Row],[Média]]-Tabela1[[#This Row],[Meta]])/Tabela1[[#This Row],[Meta]],"") -> 0.011778846 | AA45: =Tabela1[[#This Row],[Média]]-Tabela1[[#This Row],[Meta]] -> 24.5 | AB45: =VLOOKUP(Tabela1[[#This Row],[SKU]],SKU!A:B,2,0) -> COXA SBCX S/O FG 260-280g PB | AC45: =VLOOKUP(Tabela1[[#This Row],[SKU]],SKU!A:C,3,0) -> PERNA
A46: =INT(Tabela1[[#This Row],[Data e Hora2]]) -> 46244 | B46: =UPPER(TEXT(Tabela1[[#This Row],[Data Corrigida]],"MMM")) -> AGO | C46: 6a7ab139f77da7ef00271bcd | D46: 10/08/2026 17:54:09 | E46: 11/08/2026 02:20:57 | F46: Ranieli | G46: 10/08/2026 | H46: Turno 2 | I46: JOSEFA KELY NUNES DE SOUSA | J46: 13188 | K46: 1000 | L46: 1014 | M46: 994 | N46: 1025 | O46: 1021 | P46: 997 | Q46: 1008 | R46: 1013 | S46: 1018 | T46: 1014 | U46: 1010.4 | X46: 201 | Y46: =VLOOKUP(Tabela1[[#This Row],[SKU]],SKU!A:D,4,0) -> 1000 | Z46: =IFERROR((Tabela1[[#This Row],[Média]]-Tabela1[[#This Row],[Meta]])/Tabela1[[#This Row],[Meta]],"") -> 0.0104 | AA46: =Tabela1[[#This Row],[Média]]-Tabela1[[#This Row],[Meta]] -> 10.4 | AB46: =VLOOKUP(Tabela1[[#This Row],[SKU]],SKU!A:B,2,0) -> SOBRECOXA CG BDJ SE | AC46: =VLOOKUP(Tabela1[[#This Row],[SKU]],SKU!A:C,3,0) -> PERNA
A47: =INT(Tabela1[[#This Row],[Data e Hora2]]) -> 46244 | B47: =UPPER(TEXT(Tabela1[[#This Row],[Data Corrigida]],"MMM")) -> AGO | C47: 6a7ab139f77da7ef00271bd3 | D47: 10/08/2026 17:57:31 | E47: 11/08/2026 02:20:57 | F47: Ranieli | G47: 10/08/2026 | H47: Turno 2 | I47: JOSEFA KELY NUNES DE SOUSA | J47: 15229 | K47: 972 | L47: 1030 | M47: 1040 | N47: 1025 | O47: 972 | P47: 984 | Q47: 1069 | R47: 1039 | S47: 1035 | T47: 969 | U47: 1013.5 | X47: 337 | Y47: =VLOOKUP(Tabela1[[#This Row],[SKU]],SKU!A:D,4,0) -> 1000 | Z47: =IFERROR((Tabela1[[#This Row],[Média]]-Tabela1[[#This Row],[Meta]])/Tabela1[[#This Row],[Meta]],"") -> 0.0135 | AA47: =Tabela1[[#This Row],[Média]]-Tabela1[[#This Row],[Meta]] -> 13.5 | AB47: =VLOOKUP(Tabela1[[#This Row],[SKU]],SKU!A:B,2,0) -> COXA CG BDJ SE | AC47: =VLOOKUP(Tabela1[[#This Row],[SKU]],SKU!A:C,3,0) -> PERNA
A48: =INT(Tabela1[[#This Row],[Data e Hora2]]) -> 46244 | B48: =UPPER(TEXT(Tabela1[[#This Row],[Data Corrigida]],"MMM")) -> AGO | C48: 6a7ab139f77da7ef00271bd9 | D48: 10/08/2026 18:04:12 | E48: 11/08/2026 02:20:57 | F48: Ranieli | G48: 10/08/2026 | H48: Turno 2 | I48: JOSEFA KELY NUNES DE SOUSA | J48: 15105 | K48: 1044 | L48: 997 | M48: 1009 | N48: 1022 | O48: 1019 | P48: 1011 | Q48: 1031 | R48: 1040 | S48: 1015 | T48: 1078 | U48: 1026.6 | W48: assinatura | X48: 235 | Y48: =VLOOKUP(Tabela1[[#This Row],[SKU]],SKU!A:D,4,0) -> 1000 | Z48: =IFERROR((Tabela1[[#This Row],[Média]]-Tabela1[[#This Row],[Meta]])/Tabela1[[#This Row],[Meta]],"") -> 0.0266 | AA48: =Tabela1[[#This Row],[Média]]-Tabela1[[#This Row],[Meta]] -> 26.6 | AB48: =VLOOKUP(Tabela1[[#This Row],[SKU]],SKU!A:B,2,0) -> FILE PEITO MET CG BDJ SE | AC48: =VLOOKUP(Tabela1[[#This Row],[SKU]],SKU!A:C,3,0) -> PEITO
A49: =INT(Tabela1[[#This Row],[Data e Hora2]]) -> 46244 | B49: =UPPER(TEXT(Tabela1[[#This Row],[Data Corrigida]],"MMM")) -> AGO | C49: 6a7ab139f77da7ef00271bdf | D49: 10/08/2026 18:08:11 | E49: 11/08/2026 02:20:57 | F49: Ranieli | G49: 10/08/2026 | H49: Turno 2 | I49: JOSEFA KELY NUNES DE SOUSA | J49: 992093 | K49: 4983 | L49: 4998 | M49: 4869 | N49: 4978 | O49: 4949 | P49: 4986 | Q49: 4996 | R49: 5004 | S49: 5020 | T49: 4989 | U49: 4977.2 | W49: assinatura | X49: 513 | Y49: =VLOOKUP(Tabela1[[#This Row],[SKU]],SKU!A:D,4,0) -> 5000 | Z49: =IFERROR((Tabela1[[#This Row],[Média]]-Tabela1[[#This Row],[Meta]])/Tabela1[[#This Row],[Meta]],"") -> -0.00456 | AA49: =Tabela1[[#This Row],[Média]]-Tabela1[[#This Row],[Meta]] -> -22.8 | AB49: =VLOOKUP(Tabela1[[#This Row],[SKU]],SKU!A:B,2,0) -> PONTA ASA FG PB CG | AC49: =VLOOKUP(Tabela1[[#This Row],[SKU]],SKU!A:C,3,0) -> ASA
A50: =INT(Tabela1[[#This Row],[Data e Hora2]]) -> 46244 | B50: =UPPER(TEXT(Tabela1[[#This Row],[Data Corrigida]],"MMM")) -> AGO | C50: 6a7ab139f77da7ef00271bf1 | D50: 10/08/2026 22:43:22 | E50: 11/08/2026 02:20:57 | F50: Ranieli | G50: 10/08/2026 | H50: Turno 2 | I50: JOSEFA KELY NUNES DE SOUSA | J50: 15105 | K50: 1004 | L50: 1157 | M50: 1033 | N50: 1023 | O50: 1024 | P50: 1022 | Q50: 1006 | R50: 1013 | S50: 1042 | T50: 1007 | U50: 1033.1 | W50: assinatura | X50: 324 | Y50: =VLOOKUP(Tabela1[[#This Row],[SKU]],SKU!A:D,4,0) -> 1000 | Z50: =IFERROR((Tabela1[[#This Row],[Média]]-Tabela1[[#This Row],[Meta]])/Tabela1[[#This Row],[Meta]],"") -> 0.0331 | AA50: =Tabela1[[#This Row],[Média]]-Tabela1[[#This Row],[Meta]] -> 33.1 | AB50: =VLOOKUP(Tabela1[[#This Row],[SKU]],SKU!A:B,2,0) -> FILE PEITO MET CG BDJ SE | AC50: =VLOOKUP(Tabela1[[#This Row],[SKU]],SKU!A:C,3,0) -> PEITO
A51: =INT(Tabela1[[#This Row],[Data e Hora2]]) -> 46244 | B51: =UPPER(TEXT(Tabela1[[#This Row],[Data Corrigida]],"MMM")) -> AGO | C51: 6a7ab13af77da7ef00271bfd | D51: 10/08/2026 23:51:21 | E51: 11/08/2026 02:20:58 | F51: Ranieli | G51: 10/08/2026 | H51: Turno 2 | I51: JOSEFA KELY NUNES DE SOUSA | J51: 792799 | K51: 15055 | L51: 15040 | M51: 15025 | N51: 15045 | O51: 15040 | P51: 15035 | Q51: 15030 | R51: 15030 | S51: 15060 | T51: 15045 | U51: 15040.5 | W51: assinatura | X51: 3543 | Y51: =VLOOKUP(Tabela1[[#This Row],[SKU]],SKU!A:D,4,0) -> 15000 | Z51: =IFERROR((Tabela1[[#This Row],[Média]]-Tabela1[[#This Row],[Meta]])/Tabela1[[#This Row],[Meta]],"") -> 0.0027 | AA51: =Tabela1[[#This Row],[Média]]-Tabela1[[#This Row],[Meta]] -> 40.5 | AB51: =VLOOKUP(Tabela1[[#This Row],[SKU]],SKU!A:B,2,0) -> ASAS FG 100g UP LP | AC51: =VLOOKUP(Tabela1[[#This Row],[SKU]],SKU!A:C,3,0) -> ASA
...

Sheet SKU
A1: ITEM | B1: DESCRIÇÃO | C1: Família | D1: Meta
A2: 977373 | B2: MEIO ASA FG 30G UP IF LP | C2: ASA | D2: 15000
A3: 992093 | B3: PONTA ASA FG PB CG | C3: ASA | D3: 5000
A4: 209409 | B4: COXINHA DA ASA RF PC 1 KG | C4: ASA | D4: 1000
A5: 209039 | B5: COXINHA ASA IQF ALM 1KG | C5: ASA | D5: 1000
A6: 792799 | B6: ASAS FG 100g UP LP | C6: ASA | D6: 15000
A7: 963925 | B7: COXINHA DA ASA FG CG PCT | C7: ASA | D7: 18000
A8: 197742 | B8: COXINHA ASA IQF ALM SE | C8: ASA | D8: 1000
A9: 197815 | B9: MEIO ASA CG BDJ SE | C9: ASA | D9: 1000
A10: 15091 | B10: COXINHA ASA CG BDJ SE | C10: ASA | D10: 1000
A11: 958611 | B11: MEIO DA ASA IQF | C11: ASA | D11: 1000
A12: 31454 | B12: MEIO DE ASA 2,5KG IQF | C12: ASA | D12: 2500
A13: 962244 | B13: COXINHA DA ASA FG RF PCT | C13: ASA | D13: 18000
... A21: 998577 | B21: CARNE MEC SEPARADA AVE CG 15 | C21: CMS/CMR | D21: 15000
A22: 202299 | B22: CARNE MS AVES RF CB MP | C22: CMS/CMR
A23: 234309 | B23: CMS HTD8 | C23: CMS/CMR | D23: 20000
A24: 202319 | B24: CARNE MS AVES CG BL SE MP | C24: CMS/CMR | D24: 17500
A25: 18163 | B25: CORACAO FGO CG ALM SE | C25: CORAÇÃO | D25: 1000
A26: 997939 | B26: DORSO DE FRANGO BACK | C26: DORSO | D26: 10000
A27: 990457 | B27: FIGADO FG PB15,22KG PET FOOD | C27: FÍGADO | D27: 15220
A28: 15040 | B28: GORDURA FRANGO CG BL SE | C28: GORDURA ABDOMINAL | D28: 15000
A29: 797901 | B29: FRANGO INTEIRO CG PCT | C29: INTEIROS | D29: 20000
A30: 209149 | B30: FRANGO INTEIRO CG PCT | C30: INTEIROS | D30: 20000
A31: 18228 | B31: MOELA FRANGO CG ALM SE | C31: MOELA | D31: 1000
A32: 929883 | B32: FILE DE PEITO FG CG PCT | C32: PEITO | D32: 18000
A33: 15105 | B33: FILE PEITO MET CG BDJ SE | C33: PEITO | D33: 1000
A34: 209359 | B34: FILE DE PEITO RF PC 1 KG | C34: PEITO | D34: 1000
... A41: 11517 | B41: PEITO 1/2 FRANGO LIGHT CG MP | C41: PEITO | D41: 15000
A42: 224589 | B42: FILE DE PEITO EM TIRAS IQF | C42: PEITO - ANDRADINA
A43: 224579 | B43: FILE DE PEITO EM CUBOS IQF | C43: PEITO - ANDRADINA
A44: 12645 | B44: PELE DE FRANGO CG BL SE MP | C44: PELE | D44: 15000
A45: 40762 | B45: COXA SBCX LQ FG LP | C45: PERNA | D45: 10000
A46: 42838 | B46: COXA SBCX S/O FG 220-240g PB | C46: PERNA | D46: 2000
A47: 42846 | B47: COXA SBCX S/O FG 240-260g PB | C47: PERNA | D47: 2000
A48: 42854 | B48: COXA SBCX S/O FG 260-280g PB | C48: PERNA | D48: 2080
A49: 42862 | B49: COXA SBCX S/O FG 280-300g PB | C49: PERNA | D49: 2000
A50: 864048 | B50: COXA SBCX S/O 200g FG UP PB | C50: PERNA | D50: 2000
A51: 990722 | B51: COXA SBCX FG S/OP 7,5KG PB | C51: PERNA | D51: 7500
A52: 13102 | B52: COXA SBCX S/OP CG MP BL | C52: PERNA | D52: 15000
A53: 55552 | B53: COXA SBCX S/O CG MP | C53: PERNA | D53: 15000
...
