Workbook
Name SegmentaçãodeDados_Família: #N/A
Name SegmentaçãodeDados_Mês: #N/A
Name SegmentaçãodeDados_Turno1: #N/A

Sheet IC Cortes
A3: Local | B3: Turno1 | C3: Família | D3: Item1 | E3: ITEM | F3: TURNO | G3: JAN | H3: FEV | I3: MAR | J3: ABR | K3: MAI | L3: JUN | M3: JUL | N3: AGO | O3: SET | P3: OUT | Q3: NOV | R3: DEZ | S3: META | U3: =IF(U118="","",U118) -> 01/10/2026 | V3: =IF(V118="","",V118) -> 02/10/2026 | W3: =IF(W118="","",W118) -> 05/10/2026 | X3: =IF(X118="","",X118) -> 06/10/2026 | Y3: =IF(Y118="","",Y118) -> 07/10/2026 | Z3: =IF(Z118="","",Z118) -> 08/10/2026 | AA3: =IF(AA118="","",AA118) -> 09/10/2026 | AB3: =IF(AB118="","",AB118) | ... AR3: =IF(AR118="","",AR118)
A4: Meyn | B4: =F4 -> 1 | C4: Perna | D4: =IF(E4=0,D3,E4) -> Carne no Back | E4: =Coleta!H1 -> Carne no Back | F4: 1 | G4: =IFERROR(AVERAGEIFS(INDIRECT("Tabela1["&$D4&"]"),Tabela1[Turno],$F4,Tabela1[Mês],G$3),"") | H4: =IFERROR(AVERAGEIFS(INDIRECT("Tabela1["&$D4&"]"),Tabela1[Turno],$F4,Tabela1[Mês],H$3),"") | I4: =IFERROR(AVERAGEIFS(INDIRECT("Tabela1["&$D4&"]"),Tabela1[Turno],$F4,Tabela1[Mês],I$3),"") | J4: =IFERROR(AVERAGEIFS(INDIRECT("Tabela1["&$D4&"]"),Tabela1[Turno],$F4,Tabela1[Mês],J$3),"") | K4: =IFERROR(AVERAGEIFS(INDIRECT("Tabela1["&$D4&"]"),Tabela1[Turno],$F4,Tabela1[Mês],K$3),"") | L4: =IFERROR(AVERAGEIFS(INDIRECT("Tabela1["&$D4&"]"),Tabela1[Turno],$F4,Tabela1[Mês],L$3),"") | M4: =IFERROR(AVERAGEIFS(INDIRECT("Tabela1["&$D4&"]"),Tabela1[Turno],$F4,Tabela1[Mês],M$3),"") | N4: =IFERROR(AVERAGEIFS(INDIRECT("Tabela1["&$D4&"]"),Tabela1[Turno],$F4,Tabela1[Mês],N$3),"") -> 8.4 | ... R4: =IFERROR(AVERAGEIFS(INDIRECT("Tabela1["&$D4&"]"),Tabela1[Turno],$F4,Tabela1[Mês],R$3),"") | S4: 10 | U4: =IFERROR(AVERAGEIFS(INDIRECT("Tabela1["&$D4&"]"),Tabela1[Turno],$F4,Tabela1[Data],U$3),"") | V4: =IFERROR(AVERAGEIFS(INDIRECT("Tabela1["&$D4&"]"),Tabela1[Turno],$F4,Tabela1[Data],V$3),"") | W4: =IFERROR(AVERAGEIFS(INDIRECT("Tabela1["&$D4&"]"),Tabela1[Turno],$F4,Tabela1[Data],W$3),"") | X4: =IFERROR(AVERAGEIFS(INDIRECT("Tabela1["&$D4&"]"),Tabela1[Turno],$F4,Tabela1[Data],X$3),"") | Y4: =IFERROR(AVERAGEIFS(INDIRECT("Tabela1["&$D4&"]"),Tabela1[Turno],$F4,Tabela1[Data],Y$3),"") | Z4: =IFERROR(AVERAGEIFS(INDIRECT("Tabela1["&$D4&"]"),Tabela1[Turno],$F4,Tabela1[Data],Z$3),"") | AA4: =IFERROR(AVERAGEIFS(INDIRECT("Tabela1["&$D4&"]"),Tabela1[Turno],$F4,Tabela1[Data],AA$3),"") | AB4: =IFERROR(AVERAGEIFS(INDIRECT("Tabela1["&$D4&"]"),Tabela1[Turno],$F4,Tabela1[Data],AB$3),"") | ... AR4: =IFERROR(AVERAGEIFS(INDIRECT("Tabela1["&$D4&"]"),Tabela1[Turno],$F4,Tabela1[Data],AR$3),"")
A5: Meyn | B5: =F5 -> 2 | C5: Perna | D5: =IF(E5=0,D4,E5) -> Carne no Back | F5: 2 | G5: =IFERROR(AVERAGEIFS(INDIRECT("Tabela1["&$D5&"]"),Tabela1[Turno],$F5,Tabela1[Mês],G$3),"") | H5: =IFERROR(AVERAGEIFS(INDIRECT("Tabela1["&$D5&"]"),Tabela1[Turno],$F5,Tabela1[Mês],H$3),"") | I5: =IFERROR(AVERAGEIFS(INDIRECT("Tabela1["&$D5&"]"),Tabela1[Turno],$F5,Tabela1[Mês],I$3),"") | J5: =IFERROR(AVERAGEIFS(INDIRECT("Tabela1["&$D5&"]"),Tabela1[Turno],$F5,Tabela1[Mês],J$3),"") | K5: =IFERROR(AVERAGEIFS(INDIRECT("Tabela1["&$D5&"]"),Tabela1[Turno],$F5,Tabela1[Mês],K$3),"") | L5: =IFERROR(AVERAGEIFS(INDIRECT("Tabela1["&$D5&"]"),Tabela1[Turno],$F5,Tabela1[Mês],L$3),"") | M5: =IFERROR(AVERAGEIFS(INDIRECT("Tabela1["&$D5&"]"),Tabela1[Turno],$F5,Tabela1[Mês],M$3),"") | N5: =IFERROR(AVERAGEIFS(INDIRECT("Tabela1["&$D5&"]"),Tabela1[Turno],$F5,Tabela1[Mês],N$3),"") -> 6.7058824 | ... R5: =IFERROR(AVERAGEIFS(INDIRECT("Tabela1["&$D5&"]"),Tabela1[Turno],$F5,Tabela1[Mês],R$3),"") | U5: =IFERROR(AVERAGEIFS(INDIRECT("Tabela1["&$D5&"]"),Tabela1[Turno],$F5,Tabela1[Data],U$3),"") -> 7 | V5: =IFERROR(AVERAGEIFS(INDIRECT("Tabela1["&$D5&"]"),Tabela1[Turno],$F5,Tabela1[Data],V$3),"") -> 7 | W5: =IFERROR(AVERAGEIFS(INDIRECT("Tabela1["&$D5&"]"),Tabela1[Turno],$F5,Tabela1[Data],W$3),"") -> 7 | X5: =IFERROR(AVERAGEIFS(INDIRECT("Tabela1["&$D5&"]"),Tabela1[Turno],$F5,Tabela1[Data],X$3),"") -> 7 | Y5: =IFERROR(AVERAGEIFS(INDIRECT("Tabela1["&$D5&"]"),Tabela1[Turno],$F5,Tabela1[Data],Y$3),"") -> 7 | Z5: =IFERROR(AVERAGEIFS(INDIRECT("Tabela1["&$D5&"]"),Tabela1[Turno],$F5,Tabela1[Data],Z$3),"") -> 7 | AA5: =IFERROR(AVERAGEIFS(INDIRECT("Tabela1["&$D5&"]"),Tabela1[Turno],$F5,Tabela1[Data],AA$3),"") -> 7 | AB5: =IFERROR(AVERAGEIFS(INDIRECT("Tabela1["&$D5&"]"),Tabela1[Turno],$F5,Tabela1[Data],AB$3),"") | ... AR5: =IFERROR(AVERAGEIFS(INDIRECT("Tabela1["&$D5&"]"),Tabela1[Turno],$F5,Tabela1[Data],AR$3),"")
A6: Meyn | B6: =F6 -> Unidade | C6: Perna | D6: =IF(E6=0,D5,E6) -> Carne no Back | F6: Unidade | G6: =IFERROR(AVERAGEIFS(INDIRECT("Tabela1["&$D6&"]"),Tabela1[Mês],G$3),"") | H6: =IFERROR(AVERAGEIFS(INDIRECT("Tabela1["&$D6&"]"),Tabela1[Mês],H$3),"") | I6: =IFERROR(AVERAGEIFS(INDIRECT("Tabela1["&$D6&"]"),Tabela1[Mês],I$3),"") | J6: =IFERROR(AVERAGEIFS(INDIRECT("Tabela1["&$D6&"]"),Tabela1[Mês],J$3),"") | K6: =IFERROR(AVERAGEIFS(INDIRECT("Tabela1["&$D6&"]"),Tabela1[Mês],K$3),"") | L6: =IFERROR(AVERAGEIFS(INDIRECT("Tabela1["&$D6&"]"),Tabela1[Mês],L$3),"") | M6: =IFERROR(AVERAGEIFS(INDIRECT("Tabela1["&$D6&"]"),Tabela1[Mês],M$3),"") | N6: =IFERROR(AVERAGEIFS(INDIRECT("Tabela1["&$D6&"]"),Tabela1[Mês],N$3),"") -> 6.8243243 | ... R6: =IFERROR(AVERAGEIFS(INDIRECT("Tabela1["&$D6&"]"),Tabela1[Mês],R$3),"") | U6: =IFERROR(AVERAGEIFS(INDIRECT("Tabela1["&$D6&"]"),Tabela1[Data],U$3),"") -> 7 | V6: =IFERROR(AVERAGEIFS(INDIRECT("Tabela1["&$D6&"]"),Tabela1[Data],V$3),"") -> 7 | W6: =IFERROR(AVERAGEIFS(INDIRECT("Tabela1["&$D6&"]"),Tabela1[Data],W$3),"") -> 7 | X6: =IFERROR(AVERAGEIFS(INDIRECT("Tabela1["&$D6&"]"),Tabela1[Data],X$3),"") -> 7 | Y6: =IFERROR(AVERAGEIFS(INDIRECT("Tabela1["&$D6&"]"),Tabela1[Data],Y$3),"") -> 7 | Z6: =IFERROR(AVERAGEIFS(INDIRECT("Tabela1["&$D6&"]"),Tabela1[Data],Z$3),"") -> 7 | AA6: =IFERROR(AVERAGEIFS(INDIRECT("Tabela1["&$D6&"]"),Tabela1[Data],AA$3),"") -> 7 | AB6: =IFERROR(AVERAGEIFS(INDIRECT("Tabela1["&$D6&"]"),Tabela1[Data],AB$3),"") | ... AR6: =IFERROR(AVERAGEIFS(INDIRECT("Tabela1["&$D6&"]"),Tabela1[Data],AR$3),"")
A7: Meyn | B7: =F7 -> 1 | C7: Peito | D7: =IF(E7=0,D6,E7) -> Peito na Asa Meyn | E7: =Coleta!I1 -> Peito na Asa Meyn | F7: 1 | G7: =IFERROR(AVERAGEIFS(INDIRECT("Tabela1["&$D7&"]"),Tabela1[Turno],$F7,Tabela1[Mês],G$3),"") | H7: =IFERROR(AVERAGEIFS(INDIRECT("Tabela1["&$D7&"]"),Tabela1[Turno],$F7,Tabela1[Mês],H$3),"") | I7: =IFERROR(AVERAGEIFS(INDIRECT("Tabela1["&$D7&"]"),Tabela1[Turno],$F7,Tabela1[Mês],I$3),"") | J7: =IFERROR(AVERAGEIFS(INDIRECT("Tabela1["&$D7&"]"),Tabela1[Turno],$F7,Tabela1[Mês],J$3),"") | K7: =IFERROR(AVERAGEIFS(INDIRECT("Tabela1["&$D7&"]"),Tabela1[Turno],$F7,Tabela1[Mês],K$3),"") | L7: =IFERROR(AVERAGEIFS(INDIRECT("Tabela1["&$D7&"]"),Tabela1[Turno],$F7,Tabela1[Mês],L$3),"") | M7: =IFERROR(AVERAGEIFS(INDIRECT("Tabela1["&$D7&"]"),Tabela1[Turno],$F7,Tabela1[Mês],M$3),"") | N7: =IFERROR(AVERAGEIFS(INDIRECT("Tabela1["&$D7&"]"),Tabela1[Turno],$F7,Tabela1[Mês],N$3),"") -> 10 | ... R7: =IFERROR(AVERAGEIFS(INDIRECT("Tabela1["&$D7&"]"),Tabela1[Turno],$F7,Tabela1[Mês],R$3),"") | S7: 10 | U7: =IFERROR(AVERAGEIFS(INDIRECT("Tabela1["&$D7&"]"),Tabela1[Turno],$F7,Tabela1[Data],U$3),"") | V7: =IFERROR(AVERAGEIFS(INDIRECT("Tabela1["&$D7&"]"),Tabela1[Turno],$F7,Tabela1[Data],V$3),"") | W7: =IFERROR(AVERAGEIFS(INDIRECT("Tabela1["&$D7&"]"),Tabela1[Turno],$F7,Tabela1[Data],W$3),"") | X7: =IFERROR(AVERAGEIFS(INDIRECT("Tabela1["&$D7&"]"),Tabela1[Turno],$F7,Tabela1[Data],X$3),"") | Y7: =IFERROR(AVERAGEIFS(INDIRECT("Tabela1["&$D7&"]"),Tabela1[Turno],$F7,Tabela1[Data],Y$3),"") | Z7: =IFERROR(AVERAGEIFS(INDIRECT("Tabela1["&$D7&"]"),Tabela1[Turno],$F7,Tabela1[Data],Z$3),"") | AA7: =IFERROR(AVERAGEIFS(INDIRECT("Tabela1["&$D7&"]"),Tabela1[Turno],$F7,Tabela1[Data],AA$3),"") | AB7: =IFERROR(AVERAGEIFS(INDIRECT("Tabela1["&$D7&"]"),Tabela1[Turno],$F7,Tabela1[Data],AB$3),"") | ... AR7: =IFERROR(AVERAGEIFS(INDIRECT("Tabela1["&$D7&"]"),Tabela1[Turno],$F7,Tabela1[Data],AR$3),"")
A8: Meyn | B8: =F8 -> 2 | C8: Peito | D8: =IF(E8=0,D7,E8) -> Peito na Asa Meyn | F8: 2 | G8: =IFERROR(AVERAGEIFS(INDIRECT("Tabela1["&$D8&"]"),Tabela1[Turno],$F8,Tabela1[Mês],G$3),"") | H8: =IFERROR(AVERAGEIFS(INDIRECT("Tabela1["&$D8&"]"),Tabela1[Turno],$F8,Tabela1[Mês],H$3),"") | I8: =IFERROR(AVERAGEIFS(INDIRECT("Tabela1["&$D8&"]"),Tabela1[Turno],$F8,Tabela1[Mês],I$3),"") | J8: =IFERROR(AVERAGEIFS(INDIRECT("Tabela1["&$D8&"]"),Tabela1[Turno],$F8,Tabela1[Mês],J$3),"") | K8: =IFERROR(AVERAGEIFS(INDIRECT("Tabela1["&$D8&"]"),Tabela1[Turno],$F8,Tabela1[Mês],K$3),"") | L8: =IFERROR(AVERAGEIFS(INDIRECT("Tabela1["&$D8&"]"),Tabela1[Turno],$F8,Tabela1[Mês],L$3),"") | M8: =IFERROR(AVERAGEIFS(INDIRECT("Tabela1["&$D8&"]"),Tabela1[Turno],$F8,Tabela1[Mês],M$3),"") | N8: =IFERROR(AVERAGEIFS(INDIRECT("Tabela1["&$D8&"]"),Tabela1[Turno],$F8,Tabela1[Mês],N$3),"") -> 7.3142857 | ... R8: =IFERROR(AVERAGEIFS(INDIRECT("Tabela1["&$D8&"]"),Tabela1[Turno],$F8,Tabela1[Mês],R$3),"") | U8: =IFERROR(AVERAGEIFS(INDIRECT("Tabela1["&$D8&"]"),Tabela1[Turno],$F8,Tabela1[Data],U$3),"") -> 8.5 | V8: =IFERROR(AVERAGEIFS(INDIRECT("Tabela1["&$D8&"]"),Tabela1[Turno],$F8,Tabela1[Data],V$3),"") -> 7 | W8: =IFERROR(AVERAGEIFS(INDIRECT("Tabela1["&$D8&"]"),Tabela1[Turno],$F8,Tabela1[Data],W$3),"") -> 7 | X8: =IFERROR(AVERAGEIFS(INDIRECT("Tabela1["&$D8&"]"),Tabela1[Turno],$F8,Tabela1[Data],X$3),"") -> 7 | Y8: =IFERROR(AVERAGEIFS(INDIRECT("Tabela1["&$D8&"]"),Tabela1[Turno],$F8,Tabela1[Data],Y$3),"") -> 7 | Z8: =IFERROR(AVERAGEIFS(INDIRECT("Tabela1["&$D8&"]"),Tabela1[Turno],$F8,Tabela1[Data],Z$3),"") -> 7.75 | AA8: =IFERROR(AVERAGEIFS(INDIRECT("Tabela1["&$D8&"]"),Tabela1[Turno],$F8,Tabela1[Data],AA$3),"") -> 7 | AB8: =IFERROR(AVERAGEIFS(INDIRECT("Tabela1["&$D8&"]"),Tabela1[Turno],$F8,Tabela1[Data],AB$3),"") | ... AR8: =IFERROR(AVERAGEIFS(INDIRECT("Tabela1["&$D8&"]"),Tabela1[Turno],$F8,Tabela1[Data],AR$3),"")
A9: Meyn | B9: =F9 -> Unidade | C9: Peito | D9: =IF(E9=0,D8,E9) -> Peito na Asa Meyn | F9: Unidade | G9: =IFERROR(AVERAGEIFS(INDIRECT("Tabela1["&$D9&"]"),Tabela1[Mês],G$3),"") | H9: =IFERROR(AVERAGEIFS(INDIRECT("Tabela1["&$D9&"]"),Tabela1[Mês],H$3),"") | I9: =IFERROR(AVERAGEIFS(INDIRECT("Tabela1["&$D9&"]"),Tabela1[Mês],I$3),"") | J9: =IFERROR(AVERAGEIFS(INDIRECT("Tabela1["&$D9&"]"),Tabela1[Mês],J$3),"") | K9: =IFERROR(AVERAGEIFS(INDIRECT("Tabela1["&$D9&"]"),Tabela1[Mês],K$3),"") | L9: =IFERROR(AVERAGEIFS(INDIRECT("Tabela1["&$D9&"]"),Tabela1[Mês],L$3),"") | M9: =IFERROR(AVERAGEIFS(INDIRECT("Tabela1["&$D9&"]"),Tabela1[Mês],M$3),"") | N9: =IFERROR(AVERAGEIFS(INDIRECT("Tabela1["&$D9&"]"),Tabela1[Mês],N$3),"") -> 7.4868421 | ... R9: =IFERROR(AVERAGEIFS(INDIRECT("Tabela1["&$D9&"]"),Tabela1[Mês],R$3),"") | U9: =IFERROR(AVERAGEIFS(INDIRECT("Tabela1["&$D9&"]"),Tabela1[Data],U$3),"") -> 8.5 | V9: =IFERROR(AVERAGEIFS(INDIRECT("Tabela1["&$D9&"]"),Tabela1[Data],V$3),"") -> 7 | W9: =IFERROR(AVERAGEIFS(INDIRECT("Tabela1["&$D9&"]"),Tabela1[Data],W$3),"") -> 7 | X9: =IFERROR(AVERAGEIFS(INDIRECT("Tabela1["&$D9&"]"),Tabela1[Data],X$3),"") -> 7 | Y9: =IFERROR(AVERAGEIFS(INDIRECT("Tabela1["&$D9&"]"),Tabela1[Data],Y$3),"") -> 7 | Z9: =IFERROR(AVERAGEIFS(INDIRECT("Tabela1["&$D9&"]"),Tabela1[Data],Z$3),"") -> 7.75 | AA9: =IFERROR(AVERAGEIFS(INDIRECT("Tabela1["&$D9&"]"),Tabela1[Data],AA$3),"") -> 7 | AB9: =IFERROR(AVERAGEIFS(INDIRECT("Tabela1["&$D9&"]"),Tabela1[Data],AB$3),"") | ... AR9: =IFERROR(AVERAGEIFS(INDIRECT("Tabela1["&$D9&"]"),Tabela1[Data],AR$3),"")
A10: Meyn | B10: =F10 -> 1 | C10: Asa | D10: =IF(E10=0,D9,E10) -> Medalhão na Asa Meyn | E10: =Coleta!J1 -> Medalhão na Asa Meyn | F10: 1 | G10: =IFERROR(AVERAGEIFS(INDIRECT("Tabela1["&$D10&"]"),Tabela1[Turno],$F10,Tabela1[Mês],G$3),"") | H10: =IFERROR(AVERAGEIFS(INDIRECT("Tabela1["&$D10&"]"),Tabela1[Turno],$F10,Tabela1[Mês],H$3),"") | I10: =IFERROR(AVERAGEIFS(INDIRECT("Tabela1["&$D10&"]"),Tabela1[Turno],$F10,Tabela1[Mês],I$3),"") | J10: =IFERROR(AVERAGEIFS(INDIRECT("Tabela1["&$D10&"]"),Tabela1[Turno],$F10,Tabela1[Mês],J$3),"") | K10: =IFERROR(AVERAGEIFS(INDIRECT("Tabela1["&$D10&"]"),Tabela1[Turno],$F10,Tabela1[Mês],K$3),"") | L10: =IFERROR(AVERAGEIFS(INDIRECT("Tabela1["&$D10&"]"),Tabela1[Turno],$F10,Tabela1[Mês],L$3),"") | M10: =IFERROR(AVERAGEIFS(INDIRECT("Tabela1["&$D10&"]"),Tabela1[Turno],$F10,Tabela1[Mês],M$3),"") | N10: =IFERROR(AVERAGEIFS(INDIRECT("Tabela1["&$D10&"]"),Tabela1[Turno],$F10,Tabela1[Mês],N$3),"") -> 7 | ... R10: =IFERROR(AVERAGEIFS(INDIRECT("Tabela1["&$D10&"]"),Tabela1[Turno],$F10,Tabela1[Mês],R$3),"") | S10: 10 | U10: =IFERROR(AVERAGEIFS(INDIRECT("Tabela1["&$D10&"]"),Tabela1[Turno],$F10,Tabela1[Data],U$3),"") | V10: =IFERROR(AVERAGEIFS(INDIRECT("Tabela1["&$D10&"]"),Tabela1[Turno],$F10,Tabela1[Data],V$3),"") | W10: =IFERROR(AVERAGEIFS(INDIRECT("Tabela1["&$D10&"]"),Tabela1[Turno],$F10,Tabela1[Data],W$3),"") | X10: =IFERROR(AVERAGEIFS(INDIRECT("Tabela1["&$D10&"]"),Tabela1[Turno],$F10,Tabela1[Data],X$3),"") | Y10: =IFERROR(AVERAGEIFS(INDIRECT("Tabela1["&$D10&"]"),Tabela1[Turno],$F10,Tabela1[Data],Y$3),"") | Z10: =IFERROR(AVERAGEIFS(INDIRECT("Tabela1["&$D10&"]"),Tabela1[Turno],$F10,Tabela1[Data],Z$3),"") | AA10: =IFERROR(AVERAGEIFS(INDIRECT("Tabela1["&$D10&"]"),Tabela1[Turno],$F10,Tabela1[Data],AA$3),"") | AB10: =IFERROR(AVERAGEIFS(INDIRECT("Tabela1["&$D10&"]"),Tabela1[Turno],$F10,Tabela1[Data],AB$3),"") | ... AR10: =IFERROR(AVERAGEIFS(INDIRECT("Tabela1["&$D10&"]"),Tabela1[Turno],$F10,Tabela1[Data],AR$3),"")
A11: Meyn | B11: =F11 -> 2 | C11: Asa | D11: =IF(E11=0,D10,E11) -> Medalhão na Asa Meyn | F11: 2 | G11: =IFERROR(AVERAGEIFS(INDIRECT("Tabela1["&$D11&"]"),Tabela1[Turno],$F11,Tabela1[Mês],G$3),"") | H11: =IFERROR(AVERAGEIFS(INDIRECT("Tabela1["&$D11&"]"),Tabela1[Turno],$F11,Tabela1[Mês],H$3),"") | I11: =IFERROR(AVERAGEIFS(INDIRECT("Tabela1["&$D11&"]"),Tabela1[Turno],$F11,Tabela1[Mês],I$3),"") | J11: =IFERROR(AVERAGEIFS(INDIRECT("Tabela1["&$D11&"]"),Tabela1[Turno],$F11,Tabela1[Mês],J$3),"") | K11: =IFERROR(AVERAGEIFS(INDIRECT("Tabela1["&$D11&"]"),Tabela1[Turno],$F11,Tabela1[Mês],K$3),"") | L11: =IFERROR(AVERAGEIFS(INDIRECT("Tabela1["&$D11&"]"),Tabela1[Turno],$F11,Tabela1[Mês],L$3),"") | M11: =IFERROR(AVERAGEIFS(INDIRECT("Tabela1["&$D11&"]"),Tabela1[Turno],$F11,Tabela1[Mês],M$3),"") | N11: =IFERROR(AVERAGEIFS(INDIRECT("Tabela1["&$D11&"]"),Tabela1[Turno],$F11,Tabela1[Mês],N$3),"") -> 6.8857143 | ... R11: =IFERROR(AVERAGEIFS(INDIRECT("Tabela1["&$D11&"]"),Tabela1[Turno],$F11,Tabela1[Mês],R$3),"") | U11: =IFERROR(AVERAGEIFS(INDIRECT("Tabela1["&$D11&"]"),Tabela1[Turno],$F11,Tabela1[Data],U$3),"") -> 7 | V11: =IFERROR(AVERAGEIFS(INDIRECT("Tabela1["&$D11&"]"),Tabela1[Turno],$F11,Tabela1[Data],V$3),"") -> 7 | W11: =IFERROR(AVERAGEIFS(INDIRECT("Tabela1["&$D11&"]"),Tabela1[Turno],$F11,Tabela1[Data],W$3),"") -> 7 | X11: =IFERROR(AVERAGEIFS(INDIRECT("Tabela1["&$D11&"]"),Tabela1[Turno],$F11,Tabela1[Data],X$3),"") -> 7 | Y11: =IFERROR(AVERAGEIFS(INDIRECT("Tabela1["&$D11&"]"),Tabela1[Turno],$F11,Tabela1[Data],Y$3),"") -> 7 | Z11: =IFERROR(AVERAGEIFS(INDIRECT("Tabela1["&$D11&"]"),Tabela1[Turno],$F11,Tabela1[Data],Z$3),"") -> 7 | AA11: =IFERROR(AVERAGEIFS(INDIRECT("Tabela1["&$D11&"]"),Tabela1[Turno],$F11,Tabela1[Data],AA$3),"") -> 7 | AB11: =IFERROR(AVERAGEIFS(INDIRECT("Tabela1["&$D11&"]"),Tabela1[Turno],$F11,Tabela1[Data],AB$3),"") | ... AR11: =IFERROR(AVERAGEIFS(INDIRECT("Tabela1["&$D11&"]"),Tabela1[Turno],$F11,Tabela1[Data],AR$3),"")
A12: Meyn | B12: =F12 -> Unidade | C12: Asa | D12: =IF(E12=0,D11,E12) -> Medalhão na Asa Meyn | F12: Unidade | G12: =IFERROR(AVERAGEIFS(INDIRECT("Tabela1["&$D12&"]"),Tabela1[Mês],G$3),"") | H12: =IFERROR(AVERAGEIFS(INDIRECT("Tabela1["&$D12&"]"),Tabela1[Mês],H$3),"") | I12: =IFERROR(AVERAGEIFS(INDIRECT("Tabela1["&$D12&"]"),Tabela1[Mês],I$3),"") | J12: =IFERROR(AVERAGEIFS(INDIRECT("Tabela1["&$D12&"]"),Tabela1[Mês],J$3),"") | K12: =IFERROR(AVERAGEIFS(INDIRECT("Tabela1["&$D12&"]"),Tabela1[Mês],K$3),"") | L12: =IFERROR(AVERAGEIFS(INDIRECT("Tabela1["&$D12&"]"),Tabela1[Mês],L$3),"") | M12: =IFERROR(AVERAGEIFS(INDIRECT("Tabela1["&$D12&"]"),Tabela1[Mês],M$3),"") | N12: =IFERROR(AVERAGEIFS(INDIRECT("Tabela1["&$D12&"]"),Tabela1[Mês],N$3),"") -> 6.8947368 | ... R12: =IFERROR(AVERAGEIFS(INDIRECT("Tabela1["&$D12&"]"),Tabela1[Mês],R$3),"") | U12: =IFERROR(AVERAGEIFS(INDIRECT("Tabela1["&$D12&"]"),Tabela1[Data],U$3),"") -> 7 | V12: =IFERROR(AVERAGEIFS(INDIRECT("Tabela1["&$D12&"]"),Tabela1[Data],V$3),"") -> 7 | W12: =IFERROR(AVERAGEIFS(INDIRECT("Tabela1["&$D12&"]"),Tabela1[Data],W$3),"") -> 7 | X12: =IFERROR(AVERAGEIFS(INDIRECT("Tabela1["&$D12&"]"),Tabela1[Data],X$3),"") -> 7 | Y12: =IFERROR(AVERAGEIFS(INDIRECT("Tabela1["&$D12&"]"),Tabela1[Data],Y$3),"") -> 7 | Z12: =IFERROR(AVERAGEIFS(INDIRECT("Tabela1["&$D12&"]"),Tabela1[Data],Z$3),"") -> 7 | AA12: =IFERROR(AVERAGEIFS(INDIRECT("Tabela1["&$D12&"]"),Tabela1[Data],AA$3),"") -> 7 | AB12: =IFERROR(AVERAGEIFS(INDIRECT("Tabela1["&$D12&"]"),Tabela1[Data],AB$3),"") | ... AR12: =IFERROR(AVERAGEIFS(INDIRECT("Tabela1["&$D12&"]"),Tabela1[Data],AR$3),"")
A13: Meyn | B13: =F13 -> 1 | C13: Peito | D13: =IF(E13=0,D12,E13) -> Carne no Front | E13: =Coleta!K1 -> Carne no Front | F13: 1 | G13: =IFERROR(AVERAGEIFS(INDIRECT("Tabela1["&$D13&"]"),Tabela1[Turno],$F13,Tabela1[Mês],G$3),"") | H13: =IFERROR(AVERAGEIFS(INDIRECT("Tabela1["&$D13&"]"),Tabela1[Turno],$F13,Tabela1[Mês],H$3),"") | I13: =IFERROR(AVERAGEIFS(INDIRECT("Tabela1["&$D13&"]"),Tabela1[Turno],$F13,Tabela1[Mês],I$3),"") | J13: =IFERROR(AVERAGEIFS(INDIRECT("Tabela1["&$D13&"]"),Tabela1[Turno],$F13,Tabela1[Mês],J$3),"") | K13: =IFERROR(AVERAGEIFS(INDIRECT("Tabela1["&$D13&"]"),Tabela1[Turno],$F13,Tabela1[Mês],K$3),"") | L13: =IFERROR(AVERAGEIFS(INDIRECT("Tabela1["&$D13&"]"),Tabela1[Turno],$F13,Tabela1[Mês],L$3),"") | M13: =IFERROR(AVERAGEIFS(INDIRECT("Tabela1["&$D13&"]"),Tabela1[Turno],$F13,Tabela1[Mês],M$3),"") | N13: =IFERROR(AVERAGEIFS(INDIRECT("Tabela1["&$D13&"]"),Tabela1[Turno],$F13,Tabela1[Mês],N$3),"") -> 6.4 | ... R13: =IFERROR(AVERAGEIFS(INDIRECT("Tabela1["&$D13&"]"),Tabela1[Turno],$F13,Tabela1[Mês],R$3),"") | S13: 10 | U13: =IFERROR(AVERAGEIFS(INDIRECT("Tabela1["&$D13&"]"),Tabela1[Turno],$F13,Tabela1[Data],U$3),"") | V13: =IFERROR(AVERAGEIFS(INDIRECT("Tabela1["&$D13&"]"),Tabela1[Turno],$F13,Tabela1[Data],V$3),"") | W13: =IFERROR(AVERAGEIFS(INDIRECT("Tabela1["&$D13&"]"),Tabela1[Turno],$F13,Tabela1[Data],W$3),"") | X13: =IFERROR(AVERAGEIFS(INDIRECT("Tabela1["&$D13&"]"),Tabela1[Turno],$F13,Tabela1[Data],X$3),"") | Y13: =IFERROR(AVERAGEIFS(INDIRECT("Tabela1["&$D13&"]"),Tabela1[Turno],$F13,Tabela1[Data],Y$3),"") | Z13: =IFERROR(AVERAGEIFS(INDIRECT("Tabela1["&$D13&"]"),Tabela1[Turno],$F13,Tabela1[Data],Z$3),"") | AA13: =IFERROR(AVERAGEIFS(INDIRECT("Tabela1["&$D13&"]"),Tabela1[Turno],$F13,Tabela1[Data],AA$3),"") | AB13: =IFERROR(AVERAGEIFS(INDIRECT("Tabela1["&$D13&"]"),Tabela1[Turno],$F13,Tabela1[Data],AB$3),"") | ... AR13: =IFERROR(AVERAGEIFS(INDIRECT("Tabela1["&$D13&"]"),Tabela1[Turno],$F13,Tabela1[Data],AR$3),"")
A14: Meyn | B14: =F14 -> 2 | C14: Peito | D14: =IF(E14=0,D13,E14) -> Carne no Front | F14: 2 | G14: =IFERROR(AVERAGEIFS(INDIRECT("Tabela1["&$D14&"]"),Tabela1[Turno],$F14,Tabela1[Mês],G$3),"") | H14: =IFERROR(AVERAGEIFS(INDIRECT("Tabela1["&$D14&"]"),Tabela1[Turno],$F14,Tabela1[Mês],H$3),"") | I14: =IFERROR(AVERAGEIFS(INDIRECT("Tabela1["&$D14&"]"),Tabela1[Turno],$F14,Tabela1[Mês],I$3),"") | J14: =IFERROR(AVERAGEIFS(INDIRECT("Tabela1["&$D14&"]"),Tabela1[Turno],$F14,Tabela1[Mês],J$3),"") | K14: =IFERROR(AVERAGEIFS(INDIRECT("Tabela1["&$D14&"]"),Tabela1[Turno],$F14,Tabela1[Mês],K$3),"") | L14: =IFERROR(AVERAGEIFS(INDIRECT("Tabela1["&$D14&"]"),Tabela1[Turno],$F14,Tabela1[Mês],L$3),"") | M14: =IFERROR(AVERAGEIFS(INDIRECT("Tabela1["&$D14&"]"),Tabela1[Turno],$F14,Tabela1[Mês],M$3),"") | N14: =IFERROR(AVERAGEIFS(INDIRECT("Tabela1["&$D14&"]"),Tabela1[Turno],$F14,Tabela1[Mês],N$3),"") -> 5.2647059 | ... R14: =IFERROR(AVERAGEIFS(INDIRECT("Tabela1["&$D14&"]"),Tabela1[Turno],$F14,Tabela1[Mês],R$3),"") | U14: =IFERROR(AVERAGEIFS(INDIRECT("Tabela1["&$D14&"]"),Tabela1[Turno],$F14,Tabela1[Data],U$3),"") -> 5.5 | V14: =IFERROR(AVERAGEIFS(INDIRECT("Tabela1["&$D14&"]"),Tabela1[Turno],$F14,Tabela1[Data],V$3),"") -> 6 | W14: =IFERROR(AVERAGEIFS(INDIRECT("Tabela1["&$D14&"]"),Tabela1[Turno],$F14,Tabela1[Data],W$3),"") -> 5 | X14: =IFERROR(AVERAGEIFS(INDIRECT("Tabela1["&$D14&"]"),Tabela1[Turno],$F14,Tabela1[Data],X$3),"") -> 5.5 | Y14: =IFERROR(AVERAGEIFS(INDIRECT("Tabela1["&$D14&"]"),Tabela1[Turno],$F14,Tabela1[Data],Y$3),"") -> 5 | Z14: =IFERROR(AVERAGEIFS(INDIRECT("Tabela1["&$D14&"]"),Tabela1[Turno],$F14,Tabela1[Data],Z$3),"") -> 5.5 | AA14: =IFERROR(AVERAGEIFS(INDIRECT("Tabela1["&$D14&"]"),Tabela1[Turno],$F14,Tabela1[Data],AA$3),"") -> 6 | AB14: =IFERROR(AVERAGEIFS(INDIRECT("Tabela1["&$D14&"]"),Tabela1[Turno],$F14,Tabela1[Data],AB$3),"") | ... AR14: =IFERROR(AVERAGEIFS(INDIRECT("Tabela1["&$D14&"]"),Tabela1[Turno],$F14,Tabela1[Data],AR$3),"")
A15: Meyn | B15: =F15 -> Unidade | C15: Peito | D15: =IF(E15=0,D14,E15) -> Carne no Front | F15: Unidade | G15: =IFERROR(AVERAGEIFS(INDIRECT("Tabela1["&$D15&"]"),Tabela1[Mês],G$3),"") | H15: =IFERROR(AVERAGEIFS(INDIRECT("Tabela1["&$D15&"]"),Tabela1[Mês],H$3),"") | I15: =IFERROR(AVERAGEIFS(INDIRECT("Tabela1["&$D15&"]"),Tabela1[Mês],I$3),"") | J15: =IFERROR(AVERAGEIFS(INDIRECT("Tabela1["&$D15&"]"),Tabela1[Mês],J$3),"") | K15: =IFERROR(AVERAGEIFS(INDIRECT("Tabela1["&$D15&"]"),Tabela1[Mês],K$3),"") | L15: =IFERROR(AVERAGEIFS(INDIRECT("Tabela1["&$D15&"]"),Tabela1[Mês],L$3),"") | M15: =IFERROR(AVERAGEIFS(INDIRECT("Tabela1["&$D15&"]"),Tabela1[Mês],M$3),"") | N15: =IFERROR(AVERAGEIFS(INDIRECT("Tabela1["&$D15&"]"),Tabela1[Mês],N$3),"") -> 5.3378378 | ... R15: =IFERROR(AVERAGEIFS(INDIRECT("Tabela1["&$D15&"]"),Tabela1[Mês],R$3),"") | U15: =IFERROR(AVERAGEIFS(INDIRECT("Tabela1["&$D15&"]"),Tabela1[Data],U$3),"") -> 5.5 | V15: =IFERROR(AVERAGEIFS(INDIRECT("Tabela1["&$D15&"]"),Tabela1[Data],V$3),"") -> 6 | W15: =IFERROR(AVERAGEIFS(INDIRECT("Tabela1["&$D15&"]"),Tabela1[Data],W$3),"") -> 5 | X15: =IFERROR(AVERAGEIFS(INDIRECT("Tabela1["&$D15&"]"),Tabela1[Data],X$3),"") -> 5.5 | Y15: =IFERROR(AVERAGEIFS(INDIRECT("Tabela1["&$D15&"]"),Tabela1[Data],Y$3),"") -> 5 | Z15: =IFERROR(AVERAGEIFS(INDIRECT("Tabela1["&$D15&"]"),Tabela1[Data],Z$3),"") -> 5.5 | AA15: =IFERROR(AVERAGEIFS(INDIRECT("Tabela1["&$D15&"]"),Tabela1[Data],AA$3),"") -> 6 | AB15: =IFERROR(AVERAGEIFS(INDIRECT("Tabela1["&$D15&"]"),Tabela1[Data],AB$3),"") | ... AR15: =IFERROR(AVERAGEIFS(INDIRECT("Tabela1["&$D15&"]"),Tabela1[Data],AR$3),"")
A16: Meyn | B16: =F16 -> 1 | C16: Sassami | D16: =IF(E16=0,#REF!,E16) -> % Eficiência da Pinçagem | E16: =Coleta!N1 -> % Eficiência da Pinçagem | F16: 1 | G16: =IFERROR(AVERAGEIFS(INDIRECT("Tabela1["&$D16&"]"),Tabela1[Turno],$F16,Tabela1[Mês],G$3)/100,"") -> 0.6 | H16: =IFERROR(AVERAGEIFS(INDIRECT("Tabela1["&$D16&"]"),Tabela1[Turno],$F16,Tabela1[Mês],H$3)/100,"") -> 0.53 | I16: =IFERROR(AVERAGEIFS(INDIRECT("Tabela1["&$D16&"]"),Tabela1[Turno],$F16,Tabela1[Mês],I$3)/100,"") -> 0.44 | J16: =IFERROR(AVERAGEIFS(INDIRECT("Tabela1["&$D16&"]"),Tabela1[Turno],$F16,Tabela1[Mês],J$3)/100,"") -> 0.23 | K16: =IFERROR(AVERAGEIFS(INDIRECT("Tabela1["&$D16&"]"),Tabela1[Turno],$F16,Tabela1[Mês],K$3)/100,"") -> 0.49 | L16: =IFERROR(AVERAGEIFS(INDIRECT("Tabela1["&$D16&"]"),Tabela1[Turno],$F16,Tabela1[Mês],L$3)/100,"") -> 0.64 | M16: =IFERROR(AVERAGEIFS(INDIRECT("Tabela1["&$D16&"]"),Tabela1[Turno],$F16,Tabela1[Mês],M$3)/100,"") -> 0.54 | N16: =IFERROR(AVERAGEIFS(INDIRECT("Tabela1["&$D16&"]"),Tabela1[Turno],$F16,Tabela1[Mês],N$3)/100,"") -> 0.844 | ... R16: =IFERROR(AVERAGEIFS(INDIRECT("Tabela1["&$D16&"]"),Tabela1[Turno],$F16,Tabela1[Mês],R$3)/100,"") | S16: 0.95 | U16: =IFERROR(AVERAGEIFS(INDIRECT("Tabela1["&$D16&"]"),Tabela1[Turno],$F16,Tabela1[Data],U$3)/100,"") | V16: =IFERROR(AVERAGEIFS(INDIRECT("Tabela1["&$D16&"]"),Tabela1[Turno],$F16,Tabela1[Data],V$3)/100,"") | W16: =IFERROR(AVERAGEIFS(INDIRECT("Tabela1["&$D16&"]"),Tabela1[Turno],$F16,Tabela1[Data],W$3)/100,"") | X16: =IFERROR(AVERAGEIFS(INDIRECT("Tabela1["&$D16&"]"),Tabela1[Turno],$F16,Tabela1[Data],X$3)/100,"") | Y16: =IFERROR(AVERAGEIFS(INDIRECT("Tabela1["&$D16&"]"),Tabela1[Turno],$F16,Tabela1[Data],Y$3)/100,"") | Z16: =IFERROR(AVERAGEIFS(INDIRECT("Tabela1["&$D16&"]"),Tabela1[Turno],$F16,Tabela1[Data],Z$3)/100,"") | AA16: =IFERROR(AVERAGEIFS(INDIRECT("Tabela1["&$D16&"]"),Tabela1[Turno],$F16,Tabela1[Data],AA$3)/100,"") | AB16: =IFERROR(AVERAGEIFS(INDIRECT("Tabela1["&$D16&"]"),Tabela1[Turno],$F16,Tabela1[Data],AB$3)/100,"") | ... AR16: =IFERROR(AVERAGEIFS(INDIRECT("Tabela1["&$D16&"]"),Tabela1[Turno],$F16,Tabela1[Data],AR$3)/100,"")
A17: Meyn | B17: =F17 -> 2 | C17: Sassami | D17: =IF(E17=0,D16,E17) -> % Eficiência da Pinçagem | F17: 2 | G17: =IFERROR(AVERAGEIFS(INDIRECT("Tabela1["&$D17&"]"),Tabela1[Turno],$F17,Tabela1[Mês],G$3)/100,"") -> 0.58 | H17: =IFERROR(AVERAGEIFS(INDIRECT("Tabela1["&$D17&"]"),Tabela1[Turno],$F17,Tabela1[Mês],H$3)/100,"") -> 0.56 | I17: =IFERROR(AVERAGEIFS(INDIRECT("Tabela1["&$D17&"]"),Tabela1[Turno],$F17,Tabela1[Mês],I$3)/100,"") -> 0.44 | J17: =IFERROR(AVERAGEIFS(INDIRECT("Tabela1["&$D17&"]"),Tabela1[Turno],$F17,Tabela1[Mês],J$3)/100,"") -> 0.19 | K17: =IFERROR(AVERAGEIFS(INDIRECT("Tabela1["&$D17&"]"),Tabela1[Turno],$F17,Tabela1[Mês],K$3)/100,"") -> 0.57 | L17: =IFERROR(AVERAGEIFS(INDIRECT("Tabela1["&$D17&"]"),Tabela1[Turno],$F17,Tabela1[Mês],L$3)/100,"") -> 0.6 | M17: =IFERROR(AVERAGEIFS(INDIRECT("Tabela1["&$D17&"]"),Tabela1[Turno],$F17,Tabela1[Mês],M$3)/100,"") -> 0.66 | N17: =IFERROR(AVERAGEIFS(INDIRECT("Tabela1["&$D17&"]"),Tabela1[Turno],$F17,Tabela1[Mês],N$3)/100,"") -> 0.74628571 | ... R17: =IFERROR(AVERAGEIFS(INDIRECT("Tabela1["&$D17&"]"),Tabela1[Turno],$F17,Tabela1[Mês],R$3)/100,"") | U17: =IFERROR(AVERAGEIFS(INDIRECT("Tabela1["&$D17&"]"),Tabela1[Turno],$F17,Tabela1[Data],U$3)/100,"") -> 0.8075 | V17: =IFERROR(AVERAGEIFS(INDIRECT("Tabela1["&$D17&"]"),Tabela1[Turno],$F17,Tabela1[Data],V$3)/100,"") -> 0.77 | W17: =IFERROR(AVERAGEIFS(INDIRECT("Tabela1["&$D17&"]"),Tabela1[Turno],$F17,Tabela1[Data],W$3)/100,"") -> 0.84 | X17: =IFERROR(AVERAGEIFS(INDIRECT("Tabela1["&$D17&"]"),Tabela1[Turno],$F17,Tabela1[Data],X$3)/100,"") -> 0.6775 | Y17: =IFERROR(AVERAGEIFS(INDIRECT("Tabela1["&$D17&"]"),Tabela1[Turno],$F17,Tabela1[Data],Y$3)/100,"") -> 0.6375 | Z17: =IFERROR(AVERAGEIFS(INDIRECT("Tabela1["&$D17&"]"),Tabela1[Turno],$F17,Tabela1[Data],Z$3)/100,"") -> 0.7425 | AA17: =IFERROR(AVERAGEIFS(INDIRECT("Tabela1["&$D17&"]"),Tabela1[Turno],$F17,Tabela1[Data],AA$3)/100,"") -> 0.72 | AB17: =IFERROR(AVERAGEIFS(INDIRECT("Tabela1["&$D17&"]"),Tabela1[Turno],$F17,Tabela1[Data],AB$3)/100,"") | ... AR17: =IFERROR(AVERAGEIFS(INDIRECT("Tabela1["&$D17&"]"),Tabela1[Turno],$F17,Tabela1[Data],AR$3)/100,"")
A18: Meyn | B18: =F18 -> Unidade | C18: Sassami | D18: =IF(E18=0,D17,E18) -> % Eficiência da Pinçagem | F18: Unidade | G18: =IFERROR(AVERAGEIFS(INDIRECT("Tabela1["&$D18&"]"),Tabela1[Mês],G$3)/100,"") -> 0.59 | H18: =IFERROR(AVERAGEIFS(INDIRECT("Tabela1["&$D18&"]"),Tabela1[Mês],H$3)/100,"") -> 0.545 | I18: =IFERROR(AVERAGEIFS(INDIRECT("Tabela1["&$D18&"]"),Tabela1[Mês],I$3)/100,"") -> 0.44 | J18: =IFERROR(AVERAGEIFS(INDIRECT("Tabela1["&$D18&"]"),Tabela1[Mês],J$3)/100,"") -> 0.21 | K18: =IFERROR(AVERAGEIFS(INDIRECT("Tabela1["&$D18&"]"),Tabela1[Mês],K$3)/100,"") -> 0.53 | L18: =IFERROR(AVERAGEIFS(INDIRECT("Tabela1["&$D18&"]"),Tabela1[Mês],L$3)/100,"") -> 0.62 | M18: =IFERROR(AVERAGEIFS(INDIRECT("Tabela1["&$D18&"]"),Tabela1[Mês],M$3)/100,"") -> 0.6 | N18: =IFERROR(AVERAGEIFS(INDIRECT("Tabela1["&$D18&"]"),Tabela1[Mês],N$3)/100,"") -> 0.75302632 | ... R18: =IFERROR(AVERAGEIFS(INDIRECT("Tabela1["&$D18&"]"),Tabela1[Mês],R$3)/100,"") | U18: =IFERROR(AVERAGEIFS(INDIRECT("Tabela1["&$D18&"]"),Tabela1[Data],U$3)/100,"") -> 0.8075 | V18: =IFERROR(AVERAGEIFS(INDIRECT("Tabela1["&$D18&"]"),Tabela1[Data],V$3)/100,"") -> 0.77 | W18: =IFERROR(AVERAGEIFS(INDIRECT("Tabela1["&$D18&"]"),Tabela1[Data],W$3)/100,"") -> 0.84 | X18: =IFERROR(AVERAGEIFS(INDIRECT("Tabela1["&$D18&"]"),Tabela1[Data],X$3)/100,"") -> 0.6775 | Y18: =IFERROR(AVERAGEIFS(INDIRECT("Tabela1["&$D18&"]"),Tabela1[Data],Y$3)/100,"") -> 0.6375 | Z18: =IFERROR(AVERAGEIFS(INDIRECT("Tabela1["&$D18&"]"),Tabela1[Data],Z$3)/100,"") -> 0.7425 | AA18: =IFERROR(AVERAGEIFS(INDIRECT("Tabela1["&$D18&"]"),Tabela1[Data],AA$3)/100,"") -> 0.72 | AB18: =IFERROR(AVERAGEIFS(INDIRECT("Tabela1["&$D18&"]"),Tabela1[Data],AB$3)/100,"") | ... AR18: =IFERROR(AVERAGEIFS(INDIRECT("Tabela1["&$D18&"]"),Tabela1[Data],AR$3)/100,"")
A19: Meyn | B19: =F19 -> 1 | C19: Cartilagem | D19: =IF(E19=0,D18,E19) -> % Eficiência remoção cartilagem | E19: =Coleta!O1 -> % Eficiência remoção cartilagem | F19: 1 | G19: =IFERROR(AVERAGEIFS(INDIRECT("Tabela1["&$D19&"]"),Tabela1[Turno],$F19,Tabela1[Mês],G$3)/100,"") | H19: =IFERROR(AVERAGEIFS(INDIRECT("Tabela1["&$D19&"]"),Tabela1[Turno],$F19,Tabela1[Mês],H$3)/100,"") | I19: =IFERROR(AVERAGEIFS(INDIRECT("Tabela1["&$D19&"]"),Tabela1[Turno],$F19,Tabela1[Mês],I$3)/100,"") | J19: =IFERROR(AVERAGEIFS(INDIRECT("Tabela1["&$D19&"]"),Tabela1[Turno],$F19,Tabela1[Mês],J$3)/100,"") | K19: =IFERROR(AVERAGEIFS(INDIRECT("Tabela1["&$D19&"]"),Tabela1[Turno],$F19,Tabela1[Mês],K$3)/100,"") | L19: =IFERROR(AVERAGEIFS(INDIRECT("Tabela1["&$D19&"]"),Tabela1[Turno],$F19,Tabela1[Mês],L$3)/100,"") | M19: =IFERROR(AVERAGEIFS(INDIRECT("Tabela1["&$D19&"]"),Tabela1[Turno],$F19,Tabela1[Mês],M$3)/100,"") | N19: =IFERROR(AVERAGEIFS(INDIRECT("Tabela1["&$D19&"]"),Tabela1[Turno],$F19,Tabela1[Mês],N$3)/100,"") -> 0.676 | ... R19: =IFERROR(AVERAGEIFS(INDIRECT("Tabela1["&$D19&"]"),Tabela1[Turno],$F19,Tabela1[Mês],R$3)/100,"") | S19: 0.95 | U19: =IFERROR(AVERAGEIFS(INDIRECT("Tabela1["&$D19&"]"),Tabela1[Turno],$F19,Tabela1[Data],U$3)/100,"") | V19: =IFERROR(AVERAGEIFS(INDIRECT("Tabela1["&$D19&"]"),Tabela1[Turno],$F19,Tabela1[Data],V$3)/100,"") | W19: =IFERROR(AVERAGEIFS(INDIRECT("Tabela1["&$D19&"]"),Tabela1[Turno],$F19,Tabela1[Data],W$3)/100,"") | X19: =IFERROR(AVERAGEIFS(INDIRECT("Tabela1["&$D19&"]"),Tabela1[Turno],$F19,Tabela1[Data],X$3)/100,"") | Y19: =IFERROR(AVERAGEIFS(INDIRECT("Tabela1["&$D19&"]"),Tabela1[Turno],$F19,Tabela1[Data],Y$3)/100,"") | Z19: =IFERROR(AVERAGEIFS(INDIRECT("Tabela1["&$D19&"]"),Tabela1[Turno],$F19,Tabela1[Data],Z$3)/100,"") | AA19: =IFERROR(AVERAGEIFS(INDIRECT("Tabela1["&$D19&"]"),Tabela1[Turno],$F19,Tabela1[Data],AA$3)/100,"") | AB19: =IFERROR(AVERAGEIFS(INDIRECT("Tabela1["&$D19&"]"),Tabela1[Turno],$F19,Tabela1[Data],AB$3)/100,"") | ... AR19: =IFERROR(AVERAGEIFS(INDIRECT("Tabela1["&$D19&"]"),Tabela1[Turno],$F19,Tabela1[Data],AR$3)/100,"")
A20: Meyn | B20: =F20 -> 2 | C20: Cartilagem | D20: =IF(E20=0,D19,E20) -> % Eficiência remoção cartilagem | F20: 2 | G20: =IFERROR(AVERAGEIFS(INDIRECT("Tabela1["&$D20&"]"),Tabela1[Turno],$F20,Tabela1[Mês],G$3)/100,"") | H20: =IFERROR(AVERAGEIFS(INDIRECT("Tabela1["&$D20&"]"),Tabela1[Turno],$F20,Tabela1[Mês],H$3)/100,"") | I20: =IFERROR(AVERAGEIFS(INDIRECT("Tabela1["&$D20&"]"),Tabela1[Turno],$F20,Tabela1[Mês],I$3)/100,"") | J20: =IFERROR(AVERAGEIFS(INDIRECT("Tabela1["&$D20&"]"),Tabela1[Turno],$F20,Tabela1[Mês],J$3)/100,"") | K20: =IFERROR(AVERAGEIFS(INDIRECT("Tabela1["&$D20&"]"),Tabela1[Turno],$F20,Tabela1[Mês],K$3)/100,"") | L20: =IFERROR(AVERAGEIFS(INDIRECT("Tabela1["&$D20&"]"),Tabela1[Turno],$F20,Tabela1[Mês],L$3)/100,"") | M20: =IFERROR(AVERAGEIFS(INDIRECT("Tabela1["&$D20&"]"),Tabela1[Turno],$F20,Tabela1[Mês],M$3)/100,"") | N20: =IFERROR(AVERAGEIFS(INDIRECT("Tabela1["&$D20&"]"),Tabela1[Turno],$F20,Tabela1[Mês],N$3)/100,"") -> 0.68457143 | ... R20: =IFERROR(AVERAGEIFS(INDIRECT("Tabela1["&$D20&"]"),Tabela1[Turno],$F20,Tabela1[Mês],R$3)/100,"") | U20: =IFERROR(AVERAGEIFS(INDIRECT("Tabela1["&$D20&"]"),Tabela1[Turno],$F20,Tabela1[Data],U$3)/100,"") -> 0.7525 | V20: =IFERROR(AVERAGEIFS(INDIRECT("Tabela1["&$D20&"]"),Tabela1[Turno],$F20,Tabela1[Data],V$3)/100,"") -> 0.865 | W20: =IFERROR(AVERAGEIFS(INDIRECT("Tabela1["&$D20&"]"),Tabela1[Turno],$F20,Tabela1[Data],W$3)/100,"") -> 0.83666667 | X20: =IFERROR(AVERAGEIFS(INDIRECT("Tabela1["&$D20&"]"),Tabela1[Turno],$F20,Tabela1[Data],X$3)/100,"") -> 0.8275 | Y20: =IFERROR(AVERAGEIFS(INDIRECT("Tabela1["&$D20&"]"),Tabela1[Turno],$F20,Tabela1[Data],Y$3)/100,"") -> 0.7625 | Z20: =IFERROR(AVERAGEIFS(INDIRECT("Tabela1["&$D20&"]"),Tabela1[Turno],$F20,Tabela1[Data],Z$3)/100,"") -> 0.75 | AA20: =IFERROR(AVERAGEIFS(INDIRECT("Tabela1["&$D20&"]"),Tabela1[Turno],$F20,Tabela1[Data],AA$3)/100,"") -> 0.8025 | AB20: =IFERROR(AVERAGEIFS(INDIRECT("Tabela1["&$D20&"]"),Tabela1[Turno],$F20,Tabela1[Data],AB$3)/100,"") | ... AR20: =IFERROR(AVERAGEIFS(INDIRECT("Tabela1["&$D20&"]"),Tabela1[Turno],$F20,Tabela1[Data],AR$3)/100,"")
A21: Meyn | B21: =F21 -> Unidade | C21: Cartilagem | D21: =IF(E21=0,D20,E21) -> % Eficiência remoção cartilagem | F21: Unidade | G21: =IFERROR(AVERAGEIFS(INDIRECT("Tabela1["&$D21&"]"),Tabela1[Mês],G$3)/100,"") | H21: =IFERROR(AVERAGEIFS(INDIRECT("Tabela1["&$D21&"]"),Tabela1[Mês],H$3)/100,"") | I21: =IFERROR(AVERAGEIFS(INDIRECT("Tabela1["&$D21&"]"),Tabela1[Mês],I$3)/100,"") | J21: =IFERROR(AVERAGEIFS(INDIRECT("Tabela1["&$D21&"]"),Tabela1[Mês],J$3)/100,"") | K21: =IFERROR(AVERAGEIFS(INDIRECT("Tabela1["&$D21&"]"),Tabela1[Mês],K$3)/100,"") | L21: =IFERROR(AVERAGEIFS(INDIRECT("Tabela1["&$D21&"]"),Tabela1[Mês],L$3)/100,"") | M21: =IFERROR(AVERAGEIFS(INDIRECT("Tabela1["&$D21&"]"),Tabela1[Mês],M$3)/100,"") | N21: =IFERROR(AVERAGEIFS(INDIRECT("Tabela1["&$D21&"]"),Tabela1[Mês],N$3)/100,"") -> 0.68434211 | ... R21: =IFERROR(AVERAGEIFS(INDIRECT("Tabela1["&$D21&"]"),Tabela1[Mês],R$3)/100,"") | U21: =IFERROR(AVERAGEIFS(INDIRECT("Tabela1["&$D21&"]"),Tabela1[Data],U$3)/100,"") -> 0.7525 | V21: =IFERROR(AVERAGEIFS(INDIRECT("Tabela1["&$D21&"]"),Tabela1[Data],V$3)/100,"") -> 0.865 | W21: =IFERROR(AVERAGEIFS(INDIRECT("Tabela1["&$D21&"]"),Tabela1[Data],W$3)/100,"") -> 0.83666667 | X21: =IFERROR(AVERAGEIFS(INDIRECT("Tabela1["&$D21&"]"),Tabela1[Data],X$3)/100,"") -> 0.8275 | Y21: =IFERROR(AVERAGEIFS(INDIRECT("Tabela1["&$D21&"]"),Tabela1[Data],Y$3)/100,"") -> 0.7625 | Z21: =IFERROR(AVERAGEIFS(INDIRECT("Tabela1["&$D21&"]"),Tabela1[Data],Z$3)/100,"") -> 0.75 | AA21: =IFERROR(AVERAGEIFS(INDIRECT("Tabela1["&$D21&"]"),Tabela1[Data],AA$3)/100,"") -> 0.8025 | AB21: =IFERROR(AVERAGEIFS(INDIRECT("Tabela1["&$D21&"]"),Tabela1[Data],AB$3)/100,"") | ... AR21: =IFERROR(AVERAGEIFS(INDIRECT("Tabela1["&$D21&"]"),Tabela1[Data],AR$3)/100,"")
A22: Cone | B22: =F22 -> 1 | C22: Perna | D22: =IF(E22=0,D21,E22) -> Corte Perna Cone | E22: =Coleta!P1 -> Corte Perna Cone | F22: 1 | G22: =IFERROR(AVERAGEIFS(INDIRECT("Tabela1["&$D22&"]"),Tabela1[Turno],$F22,Tabela1[Mês],G$3),"") | H22: =IFERROR(AVERAGEIFS(INDIRECT("Tabela1["&$D22&"]"),Tabela1[Turno],$F22,Tabela1[Mês],H$3),"") | I22: =IFERROR(AVERAGEIFS(INDIRECT("Tabela1["&$D22&"]"),Tabela1[Turno],$F22,Tabela1[Mês],I$3),"") | J22: =IFERROR(AVERAGEIFS(INDIRECT("Tabela1["&$D22&"]"),Tabela1[Turno],$F22,Tabela1[Mês],J$3),"") | K22: =IFERROR(AVERAGEIFS(INDIRECT("Tabela1["&$D22&"]"),Tabela1[Turno],$F22,Tabela1[Mês],K$3),"") | L22: =IFERROR(AVERAGEIFS(INDIRECT("Tabela1["&$D22&"]"),Tabela1[Turno],$F22,Tabela1[Mês],L$3),"") | M22: =IFERROR(AVERAGEIFS(INDIRECT("Tabela1["&$D22&"]"),Tabela1[Turno],$F22,Tabela1[Mês],M$3),"") | N22: =IFERROR(AVERAGEIFS(INDIRECT("Tabela1["&$D22&"]"),Tabela1[Turno],$F22,Tabela1[Mês],N$3),"") -> 8.2 | ... R22: =IFERROR(AVERAGEIFS(INDIRECT("Tabela1["&$D22&"]"),Tabela1[Turno],$F22,Tabela1[Mês],R$3),"") | S22: 10 | U22: =IFERROR(AVERAGEIFS(INDIRECT("Tabela1["&$D22&"]"),Tabela1[Turno],$F22,Tabela1[Data],U$3),"") | V22: =IFERROR(AVERAGEIFS(INDIRECT("Tabela1["&$D22&"]"),Tabela1[Turno],$F22,Tabela1[Data],V$3),"") | W22: =IFERROR(AVERAGEIFS(INDIRECT("Tabela1["&$D22&"]"),Tabela1[Turno],$F22,Tabela1[Data],W$3),"") | X22: =IFERROR(AVERAGEIFS(INDIRECT("Tabela1["&$D22&"]"),Tabela1[Turno],$F22,Tabela1[Data],X$3),"") | Y22: =IFERROR(AVERAGEIFS(INDIRECT("Tabela1["&$D22&"]"),Tabela1[Turno],$F22,Tabela1[Data],Y$3),"") | Z22: =IFERROR(AVERAGEIFS(INDIRECT("Tabela1["&$D22&"]"),Tabela1[Turno],$F22,Tabela1[Data],Z$3),"") | AA22: =IFERROR(AVERAGEIFS(INDIRECT("Tabela1["&$D22&"]"),Tabela1[Turno],$F22,Tabela1[Data],AA$3),"") | AB22: =IFERROR(AVERAGEIFS(INDIRECT("Tabela1["&$D22&"]"),Tabela1[Turno],$F22,Tabela1[Data],AB$3),"") | ... AR22: =IFERROR(AVERAGEIFS(INDIRECT("Tabela1["&$D22&"]"),Tabela1[Turno],$F22,Tabela1[Data],AR$3),"")
A23: Cone | B23: =F23 -> 2 | C23: Perna | D23: =IF(E23=0,D22,E23) -> Corte Perna Cone | F23: 2 | G23: =IFERROR(AVERAGEIFS(INDIRECT("Tabela1["&$D23&"]"),Tabela1[Turno],$F23,Tabela1[Mês],G$3),"") | H23: =IFERROR(AVERAGEIFS(INDIRECT("Tabela1["&$D23&"]"),Tabela1[Turno],$F23,Tabela1[Mês],H$3),"") | I23: =IFERROR(AVERAGEIFS(INDIRECT("Tabela1["&$D23&"]"),Tabela1[Turno],$F23,Tabela1[Mês],I$3),"") | J23: =IFERROR(AVERAGEIFS(INDIRECT("Tabela1["&$D23&"]"),Tabela1[Turno],$F23,Tabela1[Mês],J$3),"") | K23: =IFERROR(AVERAGEIFS(INDIRECT("Tabela1["&$D23&"]"),Tabela1[Turno],$F23,Tabela1[Mês],K$3),"") | L23: =IFERROR(AVERAGEIFS(INDIRECT("Tabela1["&$D23&"]"),Tabela1[Turno],$F23,Tabela1[Mês],L$3),"") | M23: =IFERROR(AVERAGEIFS(INDIRECT("Tabela1["&$D23&"]"),Tabela1[Turno],$F23,Tabela1[Mês],M$3),"") | N23: =IFERROR(AVERAGEIFS(INDIRECT("Tabela1["&$D23&"]"),Tabela1[Turno],$F23,Tabela1[Mês],N$3),"") -> 6.5072464 | ... R23: =IFERROR(AVERAGEIFS(INDIRECT("Tabela1["&$D23&"]"),Tabela1[Turno],$F23,Tabela1[Mês],R$3),"") | U23: =IFERROR(AVERAGEIFS(INDIRECT("Tabela1["&$D23&"]"),Tabela1[Turno],$F23,Tabela1[Data],U$3),"") -> 6 | V23: =IFERROR(AVERAGEIFS(INDIRECT("Tabela1["&$D23&"]"),Tabela1[Turno],$F23,Tabela1[Data],V$3),"") -> 6 | W23: =IFERROR(AVERAGEIFS(INDIRECT("Tabela1["&$D23&"]"),Tabela1[Turno],$F23,Tabela1[Data],W$3),"") -> 6.3333333 | X23: =IFERROR(AVERAGEIFS(INDIRECT("Tabela1["&$D23&"]"),Tabela1[Turno],$F23,Tabela1[Data],X$3),"") -> 7 | Y23: =IFERROR(AVERAGEIFS(INDIRECT("Tabela1["&$D23&"]"),Tabela1[Turno],$F23,Tabela1[Data],Y$3),"") -> 7 | Z23: =IFERROR(AVERAGEIFS(INDIRECT("Tabela1["&$D23&"]"),Tabela1[Turno],$F23,Tabela1[Data],Z$3),"") -> 7 | AA23: =IFERROR(AVERAGEIFS(INDIRECT("Tabela1["&$D23&"]"),Tabela1[Turno],$F23,Tabela1[Data],AA$3),"") -> 6.5 | AB23: =IFERROR(AVERAGEIFS(INDIRECT("Tabela1["&$D23&"]"),Tabela1[Turno],$F23,Tabela1[Data],AB$3),"") | ... AR23: =IFERROR(AVERAGEIFS(INDIRECT("Tabela1["&$D23&"]"),Tabela1[Turno],$F23,Tabela1[Data],AR$3),"")
A24: Cone | B24: =F24 -> Unidade | C24: Perna | D24: =IF(E24=0,D23,E24) -> Corte Perna Cone | F24: Unidade | G24: =IFERROR(AVERAGEIFS(INDIRECT("Tabela1["&$D24&"]"),Tabela1[Mês],G$3),"") | H24: =IFERROR(AVERAGEIFS(INDIRECT("Tabela1["&$D24&"]"),Tabela1[Mês],H$3),"") | I24: =IFERROR(AVERAGEIFS(INDIRECT("Tabela1["&$D24&"]"),Tabela1[Mês],I$3),"") | J24: =IFERROR(AVERAGEIFS(INDIRECT("Tabela1["&$D24&"]"),Tabela1[Mês],J$3),"") | K24: =IFERROR(AVERAGEIFS(INDIRECT("Tabela1["&$D24&"]"),Tabela1[Mês],K$3),"") | L24: =IFERROR(AVERAGEIFS(INDIRECT("Tabela1["&$D24&"]"),Tabela1[Mês],L$3),"") | M24: =IFERROR(AVERAGEIFS(INDIRECT("Tabela1["&$D24&"]"),Tabela1[Mês],M$3),"") | N24: =IFERROR(AVERAGEIFS(INDIRECT("Tabela1["&$D24&"]"),Tabela1[Mês],N$3),"") -> 6.6266667 | ... R24: =IFERROR(AVERAGEIFS(INDIRECT("Tabela1["&$D24&"]"),Tabela1[Mês],R$3),"") | U24: =IFERROR(AVERAGEIFS(INDIRECT("Tabela1["&$D24&"]"),Tabela1[Data],U$3),"") -> 6 | V24: =IFERROR(AVERAGEIFS(INDIRECT("Tabela1["&$D24&"]"),Tabela1[Data],V$3),"") -> 6 | W24: =IFERROR(AVERAGEIFS(INDIRECT("Tabela1["&$D24&"]"),Tabela1[Data],W$3),"") -> 6.3333333 | X24: =IFERROR(AVERAGEIFS(INDIRECT("Tabela1["&$D24&"]"),Tabela1[Data],X$3),"") -> 7 | Y24: =IFERROR(AVERAGEIFS(INDIRECT("Tabela1["&$D24&"]"),Tabela1[Data],Y$3),"") -> 7 | Z24: =IFERROR(AVERAGEIFS(INDIRECT("Tabela1["&$D24&"]"),Tabela1[Data],Z$3),"") -> 7 | AA24: =IFERROR(AVERAGEIFS(INDIRECT("Tabela1["&$D24&"]"),Tabela1[Data],AA$3),"") -> 6.5 | AB24: =IFERROR(AVERAGEIFS(INDIRECT("Tabela1["&$D24&"]"),Tabela1[Data],AB$3),"") | ... AR24: =IFERROR(AVERAGEIFS(INDIRECT("Tabela1["&$D24&"]"),Tabela1[Data],AR$3),"")
A25: Cone | B25: =F25 -> 1 | C25: Peito | D25: =IF(E25=0,D24,E25) -> Peito na Asa Cone | E25: =Coleta!Q1 -> Peito na Asa Cone | F25: 1 | G25: =IFERROR(AVERAGEIFS(INDIRECT("Tabela1["&$D25&"]"),Tabela1[Turno],$F25,Tabela1[Mês],G$3),"") | H25: =IFERROR(AVERAGEIFS(INDIRECT("Tabela1["&$D25&"]"),Tabela1[Turno],$F25,Tabela1[Mês],H$3),"") | I25: =IFERROR(AVERAGEIFS(INDIRECT("Tabela1["&$D25&"]"),Tabela1[Turno],$F25,Tabela1[Mês],I$3),"") | J25: =IFERROR(AVERAGEIFS(INDIRECT("Tabela1["&$D25&"]"),Tabela1[Turno],$F25,Tabela1[Mês],J$3),"") | K25: =IFERROR(AVERAGEIFS(INDIRECT("Tabela1["&$D25&"]"),Tabela1[Turno],$F25,Tabela1[Mês],K$3),"") | L25: =IFERROR(AVERAGEIFS(INDIRECT("Tabela1["&$D25&"]"),Tabela1[Turno],$F25,Tabela1[Mês],L$3),"") | M25: =IFERROR(AVERAGEIFS(INDIRECT("Tabela1["&$D25&"]"),Tabela1[Turno],$F25,Tabela1[Mês],M$3),"") | N25: =IFERROR(AVERAGEIFS(INDIRECT("Tabela1["&$D25&"]"),Tabela1[Turno],$F25,Tabela1[Mês],N$3),"") -> 9.4 | ... R25: =IFERROR(AVERAGEIFS(INDIRECT("Tabela1["&$D25&"]"),Tabela1[Turno],$F25,Tabela1[Mês],R$3),"") | S25: 10 | U25: =IFERROR(AVERAGEIFS(INDIRECT("Tabela1["&$D25&"]"),Tabela1[Turno],$F25,Tabela1[Data],U$3),"") | V25: =IFERROR(AVERAGEIFS(INDIRECT("Tabela1["&$D25&"]"),Tabela1[Turno],$F25,Tabela1[Data],V$3),"") | W25: =IFERROR(AVERAGEIFS(INDIRECT("Tabela1["&$D25&"]"),Tabela1[Turno],$F25,Tabela1[Data],W$3),"") | X25: =IFERROR(AVERAGEIFS(INDIRECT("Tabela1["&$D25&"]"),Tabela1[Turno],$F25,Tabela1[Data],X$3),"") | Y25: =IFERROR(AVERAGEIFS(INDIRECT("Tabela1["&$D25&"]"),Tabela1[Turno],$F25,Tabela1[Data],Y$3),"") | Z25: =IFERROR(AVERAGEIFS(INDIRECT("Tabela1["&$D25&"]"),Tabela1[Turno],$F25,Tabela1[Data],Z$3),"") | AA25: =IFERROR(AVERAGEIFS(INDIRECT("Tabela1["&$D25&"]"),Tabela1[Turno],$F25,Tabela1[Data],AA$3),"") | AB25: =IFERROR(AVERAGEIFS(INDIRECT("Tabela1["&$D25&"]"),Tabela1[Turno],$F25,Tabela1[Data],AB$3),"") | ... AR25: =IFERROR(AVERAGEIFS(INDIRECT("Tabela1["&$D25&"]"),Tabela1[Turno],$F25,Tabela1[Data],AR$3),"")
A26: Cone | B26: =F26 -> 2 | C26: Peito | D26: =IF(E26=0,D25,E26) -> Peito na Asa Cone | F26: 2 | G26: =IFERROR(AVERAGEIFS(INDIRECT("Tabela1["&$D26&"]"),Tabela1[Turno],$F26,Tabela1[Mês],G$3),"") | H26: =IFERROR(AVERAGEIFS(INDIRECT("Tabela1["&$D26&"]"),Tabela1[Turno],$F26,Tabela1[Mês],H$3),"") | I26: =IFERROR(AVERAGEIFS(INDIRECT("Tabela1["&$D26&"]"),Tabela1[Turno],$F26,Tabela1[Mês],I$3),"") | J26: =IFERROR(AVERAGEIFS(INDIRECT("Tabela1["&$D26&"]"),Tabela1[Turno],$F26,Tabela1[Mês],J$3),"") | K26: =IFERROR(AVERAGEIFS(INDIRECT("Tabela1["&$D26&"]"),Tabela1[Turno],$F26,Tabela1[Mês],K$3),"") | L26: =IFERROR(AVERAGEIFS(INDIRECT("Tabela1["&$D26&"]"),Tabela1[Turno],$F26,Tabela1[Mês],L$3),"") | M26: =IFERROR(AVERAGEIFS(INDIRECT("Tabela1["&$D26&"]"),Tabela1[Turno],$F26,Tabela1[Mês],M$3),"") | N26: =IFERROR(AVERAGEIFS(INDIRECT("Tabela1["&$D26&"]"),Tabela1[Turno],$F26,Tabela1[Mês],N$3),"") -> 6.6029412 | ... R26: =IFERROR(AVERAGEIFS(INDIRECT("Tabela1["&$D26&"]"),Tabela1[Turno],$F26,Tabela1[Mês],R$3),"") | U26: =IFERROR(AVERAGEIFS(INDIRECT("Tabela1["&$D26&"]"),Tabela1[Turno],$F26,Tabela1[Data],U$3),"") -> 7.75 | V26: =IFERROR(AVERAGEIFS(INDIRECT("Tabela1["&$D26&"]"),Tabela1[Turno],$F26,Tabela1[Data],V$3),"") -> 7 | W26: =IFERROR(AVERAGEIFS(INDIRECT("Tabela1["&$D26&"]"),Tabela1[Turno],$F26,Tabela1[Data],W$3),"") -> 7 | X26: =IFERROR(AVERAGEIFS(INDIRECT("Tabela1["&$D26&"]"),Tabela1[Turno],$F26,Tabela1[Data],X$3),"") -> 7 | Y26: =IFERROR(AVERAGEIFS(INDIRECT("Tabela1["&$D26&"]"),Tabela1[Turno],$F26,Tabela1[Data],Y$3),"") -> 7 | Z26: =IFERROR(AVERAGEIFS(INDIRECT("Tabela1["&$D26&"]"),Tabela1[Turno],$F26,Tabela1[Data],Z$3),"") -> 7 | AA26: =IFERROR(AVERAGEIFS(INDIRECT("Tabela1["&$D26&"]"),Tabela1[Turno],$F26,Tabela1[Data],AA$3),"") -> 7 | AB26: =IFERROR(AVERAGEIFS(INDIRECT("Tabela1["&$D26&"]"),Tabela1[Turno],$F26,Tabela1[Data],AB$3),"") | ... AR26: =IFERROR(AVERAGEIFS(INDIRECT("Tabela1["&$D26&"]"),Tabela1[Turno],$F26,Tabela1[Data],AR$3),"")
A27: Cone | B27: =F27 -> Unidade | C27: Peito | D27: =IF(E27=0,D26,E27) -> Peito na Asa Cone | F27: Unidade | G27: =IFERROR(AVERAGEIFS(INDIRECT("Tabela1["&$D27&"]"),Tabela1[Mês],G$3),"") | H27: =IFERROR(AVERAGEIFS(INDIRECT("Tabela1["&$D27&"]"),Tabela1[Mês],H$3),"") | I27: =IFERROR(AVERAGEIFS(INDIRECT("Tabela1["&$D27&"]"),Tabela1[Mês],I$3),"") | J27: =IFERROR(AVERAGEIFS(INDIRECT("Tabela1["&$D27&"]"),Tabela1[Mês],J$3),"") | K27: =IFERROR(AVERAGEIFS(INDIRECT("Tabela1["&$D27&"]"),Tabela1[Mês],K$3),"") | L27: =IFERROR(AVERAGEIFS(INDIRECT("Tabela1["&$D27&"]"),Tabela1[Mês],L$3),"") | M27: =IFERROR(AVERAGEIFS(INDIRECT("Tabela1["&$D27&"]"),Tabela1[Mês],M$3),"") | N27: =IFERROR(AVERAGEIFS(INDIRECT("Tabela1["&$D27&"]"),Tabela1[Mês],N$3),"") -> 6.7972973 | ... R27: =IFERROR(AVERAGEIFS(INDIRECT("Tabela1["&$D27&"]"),Tabela1[Mês],R$3),"") | U27: =IFERROR(AVERAGEIFS(INDIRECT("Tabela1["&$D27&"]"),Tabela1[Data],U$3),"") -> 7.75 | V27: =IFERROR(AVERAGEIFS(INDIRECT("Tabela1["&$D27&"]"),Tabela1[Data],V$3),"") -> 7 | W27: =IFERROR(AVERAGEIFS(INDIRECT("Tabela1["&$D27&"]"),Tabela1[Data],W$3),"") -> 7 | X27: =IFERROR(AVERAGEIFS(INDIRECT("Tabela1["&$D27&"]"),Tabela1[Data],X$3),"") -> 7 | Y27: =IFERROR(AVERAGEIFS(INDIRECT("Tabela1["&$D27&"]"),Tabela1[Data],Y$3),"") -> 7 | Z27: =IFERROR(AVERAGEIFS(INDIRECT("Tabela1["&$D27&"]"),Tabela1[Data],Z$3),"") -> 7 | AA27: =IFERROR(AVERAGEIFS(INDIRECT("Tabela1["&$D27&"]"),Tabela1[Data],AA$3),"") -> 7 | AB27: =IFERROR(AVERAGEIFS(INDIRECT("Tabela1["&$D27&"]"),Tabela1[Data],AB$3),"") | ... AR27: =IFERROR(AVERAGEIFS(INDIRECT("Tabela1["&$D27&"]"),Tabela1[Data],AR$3),"")
A28: Cone | B28: =F28 -> 1 | C28: Asa | D28: =IF(E28=0,D27,E28) -> Medalhão na Asa Cone | E28: =Coleta!R1 -> Medalhão na Asa Cone | F28: 1 | G28: =IFERROR(AVERAGEIFS(INDIRECT("Tabela1["&$D28&"]"),Tabela1[Turno],$F28,Tabela1[Mês],G$3),"") | H28: =IFERROR(AVERAGEIFS(INDIRECT("Tabela1["&$D28&"]"),Tabela1[Turno],$F28,Tabela1[Mês],H$3),"") | I28: =IFERROR(AVERAGEIFS(INDIRECT("Tabela1["&$D28&"]"),Tabela1[Turno],$F28,Tabela1[Mês],I$3),"") | J28: =IFERROR(AVERAGEIFS(INDIRECT("Tabela1["&$D28&"]"),Tabela1[Turno],$F28,Tabela1[Mês],J$3),"") | K28: =IFERROR(AVERAGEIFS(INDIRECT("Tabela1["&$D28&"]"),Tabela1[Turno],$F28,Tabela1[Mês],K$3),"") | L28: =IFERROR(AVERAGEIFS(INDIRECT("Tabela1["&$D28&"]"),Tabela1[Turno],$F28,Tabela1[Mês],L$3),"") | M28: =IFERROR(AVERAGEIFS(INDIRECT("Tabela1["&$D28&"]"),Tabela1[Turno],$F28,Tabela1[Mês],M$3),"") | N28: =IFERROR(AVERAGEIFS(INDIRECT("Tabela1["&$D28&"]"),Tabela1[Turno],$F28,Tabela1[Mês],N$3),"") -> 8.2 | ... R28: =IFERROR(AVERAGEIFS(INDIRECT("Tabela1["&$D28&"]"),Tabela1[Turno],$F28,Tabela1[Mês],R$3),"") | S28: 10 | U28: =IFERROR(AVERAGEIFS(INDIRECT("Tabela1["&$D28&"]"),Tabela1[Turno],$F28,Tabela1[Data],U$3),"") | V28: =IFERROR(AVERAGEIFS(INDIRECT("Tabela1["&$D28&"]"),Tabela1[Turno],$F28,Tabela1[Data],V$3),"") | W28: =IFERROR(AVERAGEIFS(INDIRECT("Tabela1["&$D28&"]"),Tabela1[Turno],$F28,Tabela1[Data],W$3),"") | X28: =IFERROR(AVERAGEIFS(INDIRECT("Tabela1["&$D28&"]"),Tabela1[Turno],$F28,Tabela1[Data],X$3),"") | Y28: =IFERROR(AVERAGEIFS(INDIRECT("Tabela1["&$D28&"]"),Tabela1[Turno],$F28,Tabela1[Data],Y$3),"") | Z28: =IFERROR(AVERAGEIFS(INDIRECT("Tabela1["&$D28&"]"),Tabela1[Turno],$F28,Tabela1[Data],Z$3),"") | AA28: =IFERROR(AVERAGEIFS(INDIRECT("Tabela1["&$D28&"]"),Tabela1[Turno],$F28,Tabela1[Data],AA$3),"") | AB28: =IFERROR(AVERAGEIFS(INDIRECT("Tabela1["&$D28&"]"),Tabela1[Turno],$F28,Tabela1[Data],AB$3),"") | ... AR28: =IFERROR(AVERAGEIFS(INDIRECT("Tabela1["&$D28&"]"),Tabela1[Turno],$F28,Tabela1[Data],AR$3),"")
A29: Cone | B29: =F29 -> 2 | C29: Asa | D29: =IF(E29=0,D28,E29) -> Medalhão na Asa Cone | F29: 2 | G29: =IFERROR(AVERAGEIFS(INDIRECT("Tabela1["&$D29&"]"),Tabela1[Turno],$F29,Tabela1[Mês],G$3),"") | H29: =IFERROR(AVERAGEIFS(INDIRECT("Tabela1["&$D29&"]"),Tabela1[Turno],$F29,Tabela1[Mês],H$3),"") | I29: =IFERROR(AVERAGEIFS(INDIRECT("Tabela1["&$D29&"]"),Tabela1[Turno],$F29,Tabela1[Mês],I$3),"") | J29: =IFERROR(AVERAGEIFS(INDIRECT("Tabela1["&$D29&"]"),Tabela1[Turno],$F29,Tabela1[Mês],J$3),"") | K29: =IFERROR(AVERAGEIFS(INDIRECT("Tabela1["&$D29&"]"),Tabela1[Turno],$F29,Tabela1[Mês],K$3),"") | L29: =IFERROR(AVERAGEIFS(INDIRECT("Tabela1["&$D29&"]"),Tabela1[Turno],$F29,Tabela1[Mês],L$3),"") | M29: =IFERROR(AVERAGEIFS(INDIRECT("Tabela1["&$D29&"]"),Tabela1[Turno],$F29,Tabela1[Mês],M$3),"") | N29: =IFERROR(AVERAGEIFS(INDIRECT("Tabela1["&$D29&"]"),Tabela1[Turno],$F29,Tabela1[Mês],N$3),"") -> 6.9285714 | ... R29: =IFERROR(AVERAGEIFS(INDIRECT("Tabela1["&$D29&"]"),Tabela1[Turno],$F29,Tabela1[Mês],R$3),"") | U29: =IFERROR(AVERAGEIFS(INDIRECT("Tabela1["&$D29&"]"),Tabela1[Turno],$F29,Tabela1[Data],U$3),"") -> 7 | V29: =IFERROR(AVERAGEIFS(INDIRECT("Tabela1["&$D29&"]"),Tabela1[Turno],$F29,Tabela1[Data],V$3),"") -> 7 | W29: =IFERROR(AVERAGEIFS(INDIRECT("Tabela1["&$D29&"]"),Tabela1[Turno],$F29,Tabela1[Data],W$3),"") -> 7 | X29: =IFERROR(AVERAGEIFS(INDIRECT("Tabela1["&$D29&"]"),Tabela1[Turno],$F29,Tabela1[Data],X$3),"") -> 7 | Y29: =IFERROR(AVERAGEIFS(INDIRECT("Tabela1["&$D29&"]"),Tabela1[Turno],$F29,Tabela1[Data],Y$3),"") -> 7 | Z29: =IFERROR(AVERAGEIFS(INDIRECT("Tabela1["&$D29&"]"),Tabela1[Turno],$F29,Tabela1[Data],Z$3),"") -> 7 | AA29: =IFERROR(AVERAGEIFS(INDIRECT("Tabela1["&$D29&"]"),Tabela1[Turno],$F29,Tabela1[Data],AA$3),"") -> 7 | AB29: =IFERROR(AVERAGEIFS(INDIRECT("Tabela1["&$D29&"]"),Tabela1[Turno],$F29,Tabela1[Data],AB$3),"") | ... AR29: =IFERROR(AVERAGEIFS(INDIRECT("Tabela1["&$D29&"]"),Tabela1[Turno],$F29,Tabela1[Data],AR$3),"")
A30: Cone | B30: =F30 -> Unidade | C30: Asa | D30: =IF(E30=0,D29,E30) -> Medalhão na Asa Cone | F30: Unidade | G30: =IFERROR(AVERAGEIFS(INDIRECT("Tabela1["&$D30&"]"),Tabela1[Mês],G$3),"") | H30: =IFERROR(AVERAGEIFS(INDIRECT("Tabela1["&$D30&"]"),Tabela1[Mês],H$3),"") | I30: =IFERROR(AVERAGEIFS(INDIRECT("Tabela1["&$D30&"]"),Tabela1[Mês],I$3),"") | J30: =IFERROR(AVERAGEIFS(INDIRECT("Tabela1["&$D30&"]"),Tabela1[Mês],J$3),"") | K30: =IFERROR(AVERAGEIFS(INDIRECT("Tabela1["&$D30&"]"),Tabela1[Mês],K$3),"") | L30: =IFERROR(AVERAGEIFS(INDIRECT("Tabela1["&$D30&"]"),Tabela1[Mês],L$3),"") | M30: =IFERROR(AVERAGEIFS(INDIRECT("Tabela1["&$D30&"]"),Tabela1[Mês],M$3),"") | N30: =IFERROR(AVERAGEIFS(INDIRECT("Tabela1["&$D30&"]"),Tabela1[Mês],N$3),"") -> 7.0131579 | ... R30: =IFERROR(AVERAGEIFS(INDIRECT("Tabela1["&$D30&"]"),Tabela1[Mês],R$3),"") | U30: =IFERROR(AVERAGEIFS(INDIRECT("Tabela1["&$D30&"]"),Tabela1[Data],U$3),"") -> 7 | V30: =IFERROR(AVERAGEIFS(INDIRECT("Tabela1["&$D30&"]"),Tabela1[Data],V$3),"") -> 7 | W30: =IFERROR(AVERAGEIFS(INDIRECT("Tabela1["&$D30&"]"),Tabela1[Data],W$3),"") -> 7 | X30: =IFERROR(AVERAGEIFS(INDIRECT("Tabela1["&$D30&"]"),Tabela1[Data],X$3),"") -> 7 | Y30: =IFERROR(AVERAGEIFS(INDIRECT("Tabela1["&$D30&"]"),Tabela1[Data],Y$3),"") -> 7 | Z30: =IFERROR(AVERAGEIFS(INDIRECT("Tabela1["&$D30&"]"),Tabela1[Data],Z$3),"") -> 7 | AA30: =IFERROR(AVERAGEIFS(INDIRECT("Tabela1["&$D30&"]"),Tabela1[Data],AA$3),"") -> 7 | AB30: =IFERROR(AVERAGEIFS(INDIRECT("Tabela1["&$D30&"]"),Tabela1[Data],AB$3),"") | ... AR30: =IFERROR(AVERAGEIFS(INDIRECT("Tabela1["&$D30&"]"),Tabela1[Data],AR$3),"")
A31: Cone | B31: =F31 -> 1 | C31: Peito | D31: =IF(E31=0,D30,E31) -> Corte Peito Cone | E31: =Coleta!S1 -> Corte Peito Cone | F31: 1 | G31: =IFERROR(AVERAGEIFS(INDIRECT("Tabela1["&$D31&"]"),Tabela1[Turno],$F31,Tabela1[Mês],G$3),"") | H31: =IFERROR(AVERAGEIFS(INDIRECT("Tabela1["&$D31&"]"),Tabela1[Turno],$F31,Tabela1[Mês],H$3),"") | I31: =IFERROR(AVERAGEIFS(INDIRECT("Tabela1["&$D31&"]"),Tabela1[Turno],$F31,Tabela1[Mês],I$3),"") | J31: =IFERROR(AVERAGEIFS(INDIRECT("Tabela1["&$D31&"]"),Tabela1[Turno],$F31,Tabela1[Mês],J$3),"") | K31: =IFERROR(AVERAGEIFS(INDIRECT("Tabela1["&$D31&"]"),Tabela1[Turno],$F31,Tabela1[Mês],K$3),"") | L31: =IFERROR(AVERAGEIFS(INDIRECT("Tabela1["&$D31&"]"),Tabela1[Turno],$F31,Tabela1[Mês],L$3),"") | M31: =IFERROR(AVERAGEIFS(INDIRECT("Tabela1["&$D31&"]"),Tabela1[Turno],$F31,Tabela1[Mês],M$3),"") | N31: =IFERROR(AVERAGEIFS(INDIRECT("Tabela1["&$D31&"]"),Tabela1[Turno],$F31,Tabela1[Mês],N$3),"") -> 7.8 | ... R31: =IFERROR(AVERAGEIFS(INDIRECT("Tabela1["&$D31&"]"),Tabela1[Turno],$F31,Tabela1[Mês],R$3),"") | S31: 10 | U31: =IFERROR(AVERAGEIFS(INDIRECT("Tabela1["&$D31&"]"),Tabela1[Turno],$F31,Tabela1[Data],U$3),"") | V31: =IFERROR(AVERAGEIFS(INDIRECT("Tabela1["&$D31&"]"),Tabela1[Turno],$F31,Tabela1[Data],V$3),"") | W31: =IFERROR(AVERAGEIFS(INDIRECT("Tabela1["&$D31&"]"),Tabela1[Turno],$F31,Tabela1[Data],W$3),"") | X31: =IFERROR(AVERAGEIFS(INDIRECT("Tabela1["&$D31&"]"),Tabela1[Turno],$F31,Tabela1[Data],X$3),"") | Y31: =IFERROR(AVERAGEIFS(INDIRECT("Tabela1["&$D31&"]"),Tabela1[Turno],$F31,Tabela1[Data],Y$3),"") | Z31: =IFERROR(AVERAGEIFS(INDIRECT("Tabela1["&$D31&"]"),Tabela1[Turno],$F31,Tabela1[Data],Z$3),"") | AA31: =IFERROR(AVERAGEIFS(INDIRECT("Tabela1["&$D31&"]"),Tabela1[Turno],$F31,Tabela1[Data],AA$3),"") | AB31: =IFERROR(AVERAGEIFS(INDIRECT("Tabela1["&$D31&"]"),Tabela1[Turno],$F31,Tabela1[Data],AB$3),"") | ... AR31: =IFERROR(AVERAGEIFS(INDIRECT("Tabela1["&$D31&"]"),Tabela1[Turno],$F31,Tabela1[Data],AR$3),"")
A32: Cone | B32: =F32 -> 2 | C32: Peito | D32: =IF(E32=0,D31,E32) -> Corte Peito Cone | F32: 2 | G32: =IFERROR(AVERAGEIFS(INDIRECT("Tabela1["&$D32&"]"),Tabela1[Turno],$F32,Tabela1[Mês],G$3),"") | H32: =IFERROR(AVERAGEIFS(INDIRECT("Tabela1["&$D32&"]"),Tabela1[Turno],$F32,Tabela1[Mês],H$3),"") | I32: =IFERROR(AVERAGEIFS(INDIRECT("Tabela1["&$D32&"]"),Tabela1[Turno],$F32,Tabela1[Mês],I$3),"") | J32: =IFERROR(AVERAGEIFS(INDIRECT("Tabela1["&$D32&"]"),Tabela1[Turno],$F32,Tabela1[Mês],J$3),"") | K32: =IFERROR(AVERAGEIFS(INDIRECT("Tabela1["&$D32&"]"),Tabela1[Turno],$F32,Tabela1[Mês],K$3),"") | L32: =IFERROR(AVERAGEIFS(INDIRECT("Tabela1["&$D32&"]"),Tabela1[Turno],$F32,Tabela1[Mês],L$3),"") | M32: =IFERROR(AVERAGEIFS(INDIRECT("Tabela1["&$D32&"]"),Tabela1[Turno],$F32,Tabela1[Mês],M$3),"") | N32: =IFERROR(AVERAGEIFS(INDIRECT("Tabela1["&$D32&"]"),Tabela1[Turno],$F32,Tabela1[Mês],N$3),"") -> 6.9275362 | ... R32: =IFERROR(AVERAGEIFS(INDIRECT("Tabela1["&$D32&"]"),Tabela1[Turno],$F32,Tabela1[Mês],R$3),"") | U32: =IFERROR(AVERAGEIFS(INDIRECT("Tabela1["&$D32&"]"),Tabela1[Turno],$F32,Tabela1[Data],U$3),"") -> 7 | V32: =IFERROR(AVERAGEIFS(INDIRECT("Tabela1["&$D32&"]"),Tabela1[Turno],$F32,Tabela1[Data],V$3),"") -> 7 | W32: =IFERROR(AVERAGEIFS(INDIRECT("Tabela1["&$D32&"]"),Tabela1[Turno],$F32,Tabela1[Data],W$3),"") -> 6.3333333 | X32: =IFERROR(AVERAGEIFS(INDIRECT("Tabela1["&$D32&"]"),Tabela1[Turno],$F32,Tabela1[Data],X$3),"") -> 7 | Y32: =IFERROR(AVERAGEIFS(INDIRECT("Tabela1["&$D32&"]"),Tabela1[Turno],$F32,Tabela1[Data],Y$3),"") -> 7 | Z32: =IFERROR(AVERAGEIFS(INDIRECT("Tabela1["&$D32&"]"),Tabela1[Turno],$F32,Tabela1[Data],Z$3),"") -> 7 | AA32: =IFERROR(AVERAGEIFS(INDIRECT("Tabela1["&$D32&"]"),Tabela1[Turno],$F32,Tabela1[Data],AA$3),"") -> 7 | AB32: =IFERROR(AVERAGEIFS(INDIRECT("Tabela1["&$D32&"]"),Tabela1[Turno],$F32,Tabela1[Data],AB$3),"") | ... AR32: =IFERROR(AVERAGEIFS(INDIRECT("Tabela1["&$D32&"]"),Tabela1[Turno],$F32,Tabela1[Data],AR$3),"")
A33: Cone | B33: =F33 -> Unidade | C33: Peito | D33: =IF(E33=0,D32,E33) -> Corte Peito Cone | F33: Unidade | G33: =IFERROR(AVERAGEIFS(INDIRECT("Tabela1["&$D33&"]"),Tabela1[Mês],G$3),"") | H33: =IFERROR(AVERAGEIFS(INDIRECT("Tabela1["&$D33&"]"),Tabela1[Mês],H$3),"") | I33: =IFERROR(AVERAGEIFS(INDIRECT("Tabela1["&$D33&"]"),Tabela1[Mês],I$3),"") | J33: =IFERROR(AVERAGEIFS(INDIRECT("Tabela1["&$D33&"]"),Tabela1[Mês],J$3),"") | K33: =IFERROR(AVERAGEIFS(INDIRECT("Tabela1["&$D33&"]"),Tabela1[Mês],K$3),"") | L33: =IFERROR(AVERAGEIFS(INDIRECT("Tabela1["&$D33&"]"),Tabela1[Mês],L$3),"") | M33: =IFERROR(AVERAGEIFS(INDIRECT("Tabela1["&$D33&"]"),Tabela1[Mês],M$3),"") | N33: =IFERROR(AVERAGEIFS(INDIRECT("Tabela1["&$D33&"]"),Tabela1[Mês],N$3),"") -> 6.9866667 | ... R33: =IFERROR(AVERAGEIFS(INDIRECT("Tabela1["&$D33&"]"),Tabela1[Mês],R$3),"") | U33: =IFERROR(AVERAGEIFS(INDIRECT("Tabela1["&$D33&"]"),Tabela1[Data],U$3),"") -> 7 | V33: =IFERROR(AVERAGEIFS(INDIRECT("Tabela1["&$D33&"]"),Tabela1[Data],V$3),"") -> 7 | W33: =IFERROR(AVERAGEIFS(INDIRECT("Tabela1["&$D33&"]"),Tabela1[Data],W$3),"") -> 6.3333333 | X33: =IFERROR(AVERAGEIFS(INDIRECT("Tabela1["&$D33&"]"),Tabela1[Data],X$3),"") -> 7 | Y33: =IFERROR(AVERAGEIFS(INDIRECT("Tabela1["&$D33&"]"),Tabela1[Data],Y$3),"") -> 7 | Z33: =IFERROR(AVERAGEIFS(INDIRECT("Tabela1["&$D33&"]"),Tabela1[Data],Z$3),"") -> 7 | AA33: =IFERROR(AVERAGEIFS(INDIRECT("Tabela1["&$D33&"]"),Tabela1[Data],AA$3),"") -> 7 | AB33: =IFERROR(AVERAGEIFS(INDIRECT("Tabela1["&$D33&"]"),Tabela1[Data],AB$3),"") | ... AR33: =IFERROR(AVERAGEIFS(INDIRECT("Tabela1["&$D33&"]"),Tabela1[Data],AR$3),"")
A34: Cone | B34: =F34 -> 1 | C34: Sassami | D34: =IF(E34=0,D33,E34) -> Corte Sassami Cone | E34: =Coleta!T1 -> Corte Sassami Cone | F34: 1 | G34: =IFERROR(AVERAGEIFS(INDIRECT("Tabela1["&$D34&"]"),Tabela1[Turno],$F34,Tabela1[Mês],G$3),"") | H34: =IFERROR(AVERAGEIFS(INDIRECT("Tabela1["&$D34&"]"),Tabela1[Turno],$F34,Tabela1[Mês],H$3),"") | I34: =IFERROR(AVERAGEIFS(INDIRECT("Tabela1["&$D34&"]"),Tabela1[Turno],$F34,Tabela1[Mês],I$3),"") | J34: =IFERROR(AVERAGEIFS(INDIRECT("Tabela1["&$D34&"]"),Tabela1[Turno],$F34,Tabela1[Mês],J$3),"") | K34: =IFERROR(AVERAGEIFS(INDIRECT("Tabela1["&$D34&"]"),Tabela1[Turno],$F34,Tabela1[Mês],K$3),"") | L34: =IFERROR(AVERAGEIFS(INDIRECT("Tabela1["&$D34&"]"),Tabela1[Turno],$F34,Tabela1[Mês],L$3),"") | M34: =IFERROR(AVERAGEIFS(INDIRECT("Tabela1["&$D34&"]"),Tabela1[Turno],$F34,Tabela1[Mês],M$3),"") | N34: =IFERROR(AVERAGEIFS(INDIRECT("Tabela1["&$D34&"]"),Tabela1[Turno],$F34,Tabela1[Mês],N$3),"") -> 7.2 | ... R34: =IFERROR(AVERAGEIFS(INDIRECT("Tabela1["&$D34&"]"),Tabela1[Turno],$F34,Tabela1[Mês],R$3),"") | S34: 10 | U34: =IFERROR(AVERAGEIFS(INDIRECT("Tabela1["&$D34&"]"),Tabela1[Turno],$F34,Tabela1[Data],U$3),"") | V34: =IFERROR(AVERAGEIFS(INDIRECT("Tabela1["&$D34&"]"),Tabela1[Turno],$F34,Tabela1[Data],V$3),"") | W34: =IFERROR(AVERAGEIFS(INDIRECT("Tabela1["&$D34&"]"),Tabela1[Turno],$F34,Tabela1[Data],W$3),"") | X34: =IFERROR(AVERAGEIFS(INDIRECT("Tabela1["&$D34&"]"),Tabela1[Turno],$F34,Tabela1[Data],X$3),"") | Y34: =IFERROR(AVERAGEIFS(INDIRECT("Tabela1["&$D34&"]"),Tabela1[Turno],$F34,Tabela1[Data],Y$3),"") | Z34: =IFERROR(AVERAGEIFS(INDIRECT("Tabela1["&$D34&"]"),Tabela1[Turno],$F34,Tabela1[Data],Z$3),"") | AA34: =IFERROR(AVERAGEIFS(INDIRECT("Tabela1["&$D34&"]"),Tabela1[Turno],$F34,Tabela1[Data],AA$3),"") | AB34: =IFERROR(AVERAGEIFS(INDIRECT("Tabela1["&$D34&"]"),Tabela1[Turno],$F34,Tabela1[Data],AB$3),"") | ... AR34: =IFERROR(AVERAGEIFS(INDIRECT("Tabela1["&$D34&"]"),Tabela1[Turno],$F34,Tabela1[Data],AR$3),"")
